extra_output_errors_list:  
test hysteresis_magic.py: [Errno 2] No such file or directory.  
Traceback below: 
  File "/Users/nebula/Python/PmagPy/Command_line_Tests/error_logging.py", line 27, in go_through
    v()
  File "Extra_output.py", line 244, in complete_hysteresis_magic_test
    hysteresis_magic.run_program()
  File "Extra_output.py", line 63, in run_program
    obj = env.run(self.name, '-WD', directory, '-f', self.infile, self.tag1, self.outfile1, self.tag2, self.outfile2, self.arg1, self.arg2, self.arg3, self.arg4, stdin=self.stdin)
  File "/Library/Frameworks/Python.framework/Versions/7.3/lib/python2.7/site-packages/ScriptTest-1.2-py2.7.egg/scripttest/__init__.py", line 237, in run
    env=clean_environ(self.environ))
  File "/Library/Frameworks/Python.framework/Versions/7.3/lib/python2.7/subprocess.py", line 679, in __init__
    errread, errwrite)
  File "/Library/Frameworks/Python.framework/Versions/7.3/lib/python2.7/subprocess.py", line 1249, in _execute_child
    raise child_exception

test IODP_csv.py: [Errno 2] No such file or directory.  
Traceback below: 
  File "/Users/nebula/Python/PmagPy/Command_line_Tests/error_logging.py", line 27, in go_through
    v()
  File "Extra_output.py", line 435, in complete_IODP_csv_magic_test
    obj = env.run('IODP_csv_magic.py', '-h')
  File "/Library/Frameworks/Python.framework/Versions/7.3/lib/python2.7/site-packages/ScriptTest-1.2-py2.7.egg/scripttest/__init__.py", line 237, in run
    env=clean_environ(self.environ))
  File "/Library/Frameworks/Python.framework/Versions/7.3/lib/python2.7/subprocess.py", line 679, in __init__
    errread, errwrite)
  File "/Library/Frameworks/Python.framework/Versions/7.3/lib/python2.7/subprocess.py", line 1249, in _execute_child
    raise child_exception

None: [Errno 2] No such file or directory.  
Traceback below: 
  File "/Users/nebula/Python/PmagPy/Command_line_Tests/error_logging.py", line 27, in go_through
    v()
  File "Extra_output.py", line 460, in complete_SUFAR4_asc_magic_test
    sufar4.ex_out_sequence()
  File "Extra_output.py", line 139, in ex_out_sequence
    self.run_program()
  File "Extra_output.py", line 63, in run_program
    obj = env.run(self.name, '-WD', directory, '-f', self.infile, self.tag1, self.outfile1, self.tag2, self.outfile2, self.arg1, self.arg2, self.arg3, self.arg4, stdin=self.stdin)
  File "/Library/Frameworks/Python.framework/Versions/7.3/lib/python2.7/site-packages/ScriptTest-1.2-py2.7.egg/scripttest/__init__.py", line 237, in run
    env=clean_environ(self.environ))
  File "/Library/Frameworks/Python.framework/Versions/7.3/lib/python2.7/subprocess.py", line 679, in __init__
    errread, errwrite)
  File "/Library/Frameworks/Python.framework/Versions/7.3/lib/python2.7/subprocess.py", line 1249, in _execute_child
    raise child_exception

test pmag_results_extract.py: [Errno 2] No such file or directory.  
Traceback below: 
  File "/Users/nebula/Python/PmagPy/Command_line_Tests/error_logging.py", line 27, in go_through
    v()
  File "Extra_output.py", line 318, in complete_pmag_results_extract_test
    obj = env.run('pmag_results_extract.py', '-WD', directory, '-f', 'pmag_results_extract.dat')
  File "/Library/Frameworks/Python.framework/Versions/7.3/lib/python2.7/site-packages/ScriptTest-1.2-py2.7.egg/scripttest/__init__.py", line 237, in run
    env=clean_environ(self.environ))
  File "/Library/Frameworks/Python.framework/Versions/7.3/lib/python2.7/subprocess.py", line 679, in __init__
    errread, errwrite)
  File "/Library/Frameworks/Python.framework/Versions/7.3/lib/python2.7/subprocess.py", line 1249, in _execute_child
    raise child_exception

test parse_measurements_test(): [Errno 2] No such file or directory.  
Traceback below: 
  File "/Users/nebula/Python/PmagPy/Command_line_Tests/error_logging.py", line 27, in go_through
    v()
  File "Extra_output.py", line 353, in complete_parse_measurements_test
    parse_measurements.ex_out_sequence()
  File "Extra_output.py", line 139, in ex_out_sequence
    self.run_program()
  File "Extra_output.py", line 63, in run_program
    obj = env.run(self.name, '-WD', directory, '-f', self.infile, self.tag1, self.outfile1, self.tag2, self.outfile2, self.arg1, self.arg2, self.arg3, self.arg4, stdin=self.stdin)
  File "/Library/Frameworks/Python.framework/Versions/7.3/lib/python2.7/site-packages/ScriptTest-1.2-py2.7.egg/scripttest/__init__.py", line 237, in run
    env=clean_environ(self.environ))
  File "/Library/Frameworks/Python.framework/Versions/7.3/lib/python2.7/subprocess.py", line 679, in __init__
    errread, errwrite)
  File "/Library/Frameworks/Python.framework/Versions/7.3/lib/python2.7/subprocess.py", line 1249, in _execute_child
    raise child_exception

None: [Errno 2] No such file or directory.  
Traceback below: 
  File "/Users/nebula/Python/PmagPy/Command_line_Tests/error_logging.py", line 27, in go_through
    v()
  File "Extra_output.py", line 476, in complete_specimens_results_magic_test
    obj = env.run('specimens_results_magic.py', '-h', cwd = directory + '/specimens_results_magic')
  File "/Library/Frameworks/Python.framework/Versions/7.3/lib/python2.7/site-packages/ScriptTest-1.2-py2.7.egg/scripttest/__init__.py", line 237, in run
    env=clean_environ(self.environ))
  File "/Library/Frameworks/Python.framework/Versions/7.3/lib/python2.7/subprocess.py", line 679, in __init__
    errread, errwrite)
  File "/Library/Frameworks/Python.framework/Versions/7.3/lib/python2.7/subprocess.py", line 1249, in _execute_child
    raise child_exception

test thellier_magic_redo.py: [Errno 2] No such file or directory.  
Traceback below: 
  File "/Users/nebula/Python/PmagPy/Command_line_Tests/error_logging.py", line 27, in go_through
    v()
  File "Extra_output.py", line 371, in complete_thellier_magic_redo_test
    obj = env.run("thellier_magic_redo.py", "-WD", directory, "-f", infile, in_tag1, in1, in_tag2, in2, in_tag3, in3, "-F", outfile, out_tag1, out1, out_tag2, out2, arg1, arg2)
  File "/Library/Frameworks/Python.framework/Versions/7.3/lib/python2.7/site-packages/ScriptTest-1.2-py2.7.egg/scripttest/__init__.py", line 237, in run
    env=clean_environ(self.environ))
  File "/Library/Frameworks/Python.framework/Versions/7.3/lib/python2.7/subprocess.py", line 679, in __init__
    errread, errwrite)
  File "/Library/Frameworks/Python.framework/Versions/7.3/lib/python2.7/subprocess.py", line 1249, in _execute_child
    raise child_exception

test kly4s_magic.py: [Errno 2] No such file or directory.  
Traceback below: 
  File "/Users/nebula/Python/PmagPy/Command_line_Tests/error_logging.py", line 27, in go_through
    v()
  File "Extra_output.py", line 295, in complete_kly4s_magic_test
    obj = env.run('kly4s_magic.py', '-WD', directory, '-f', kly4s_infile, '-F', kly4s_F, '-Fa', kly4s_Fa)
  File "/Library/Frameworks/Python.framework/Versions/7.3/lib/python2.7/site-packages/ScriptTest-1.2-py2.7.egg/scripttest/__init__.py", line 237, in run
    env=clean_environ(self.environ))
  File "/Library/Frameworks/Python.framework/Versions/7.3/lib/python2.7/subprocess.py", line 679, in __init__
    errread, errwrite)
  File "/Library/Frameworks/Python.framework/Versions/7.3/lib/python2.7/subprocess.py", line 1249, in _execute_child
    raise child_exception

test CIT_magic.py: [Errno 2] No such file or directory.  
Traceback below: 
  File "/Users/nebula/Python/PmagPy/Command_line_Tests/error_logging.py", line 27, in go_through
    v()
  File "Extra_output.py", line 389, in complete_CIT_magic_test
    obj= env.run('CIT_magic.py', '-WD', directory, '-h')
  File "/Library/Frameworks/Python.framework/Versions/7.3/lib/python2.7/site-packages/ScriptTest-1.2-py2.7.egg/scripttest/__init__.py", line 237, in run
    env=clean_environ(self.environ))
  File "/Library/Frameworks/Python.framework/Versions/7.3/lib/python2.7/subprocess.py", line 679, in __init__
    errread, errwrite)
  File "/Library/Frameworks/Python.framework/Versions/7.3/lib/python2.7/subprocess.py", line 1249, in _execute_child
    raise child_exception

test k15_magic.py: [Errno 2] No such file or directory.  
Traceback below: 
  File "/Users/nebula/Python/PmagPy/Command_line_Tests/error_logging.py", line 27, in go_through
    v()
  File "Extra_output.py", line 265, in complete_k15_magic_test
    obj = env.run('k15_magic.py', '-WD', directory, '-f', k15_infile, '-Fsa', k15_Fsa, '-Fa', k15_Fa, '-F', k15_F)
  File "/Library/Frameworks/Python.framework/Versions/7.3/lib/python2.7/site-packages/ScriptTest-1.2-py2.7.egg/scripttest/__init__.py", line 237, in run
    env=clean_environ(self.environ))
  File "/Library/Frameworks/Python.framework/Versions/7.3/lib/python2.7/subprocess.py", line 679, in __init__
    errread, errwrite)
  File "/Library/Frameworks/Python.framework/Versions/7.3/lib/python2.7/subprocess.py", line 1249, in _execute_child
    raise child_exception

None: [Errno 2] No such file or directory.  
Traceback below: 
  File "/Users/nebula/Python/PmagPy/Command_line_Tests/error_logging.py", line 27, in go_through
    v()
  File "Extra_output.py", line 450, in complete_PMD_magic_test
    PMD_magic.ex_out_sequence()
  File "Extra_output.py", line 139, in ex_out_sequence
    self.run_program()
  File "Extra_output.py", line 63, in run_program
    obj = env.run(self.name, '-WD', directory, '-f', self.infile, self.tag1, self.outfile1, self.tag2, self.outfile2, self.arg1, self.arg2, self.arg3, self.arg4, stdin=self.stdin)
  File "/Library/Frameworks/Python.framework/Versions/7.3/lib/python2.7/site-packages/ScriptTest-1.2-py2.7.egg/scripttest/__init__.py", line 237, in run
    env=clean_environ(self.environ))
  File "/Library/Frameworks/Python.framework/Versions/7.3/lib/python2.7/subprocess.py", line 679, in __init__
    errread, errwrite)
  File "/Library/Frameworks/Python.framework/Versions/7.3/lib/python2.7/subprocess.py", line 1249, in _execute_child
    raise child_exception

testing aarm_magic.py: [Errno 2] No such file or directory.  
Traceback below: 
  File "/Users/nebula/Python/PmagPy/Command_line_Tests/error_logging.py", line 27, in go_through
    v()
  File "Extra_output.py", line 220, in complete_aarm_magic_test
    aarm_magic.ex_out_sequence()
  File "Extra_output.py", line 139, in ex_out_sequence
    self.run_program()
  File "Extra_output.py", line 63, in run_program
    obj = env.run(self.name, '-WD', directory, '-f', self.infile, self.tag1, self.outfile1, self.tag2, self.outfile2, self.arg1, self.arg2, self.arg3, self.arg4, stdin=self.stdin)
  File "/Library/Frameworks/Python.framework/Versions/7.3/lib/python2.7/site-packages/ScriptTest-1.2-py2.7.egg/scripttest/__init__.py", line 237, in run
    env=clean_environ(self.environ))
  File "/Library/Frameworks/Python.framework/Versions/7.3/lib/python2.7/subprocess.py", line 679, in __init__
    errread, errwrite)
  File "/Library/Frameworks/Python.framework/Versions/7.3/lib/python2.7/subprocess.py", line 1249, in _execute_child
    raise child_exception

test atrm_magic.py: [Errno 2] No such file or directory.  
Traceback below: 
  File "/Users/nebula/Python/PmagPy/Command_line_Tests/error_logging.py", line 27, in go_through
    v()
  File "Extra_output.py", line 231, in complete_atrm_magic_test
    atrm.ex_out_sequence()
  File "Extra_output.py", line 139, in ex_out_sequence
    self.run_program()
  File "Extra_output.py", line 63, in run_program
    obj = env.run(self.name, '-WD', directory, '-f', self.infile, self.tag1, self.outfile1, self.tag2, self.outfile2, self.arg1, self.arg2, self.arg3, self.arg4, stdin=self.stdin)
  File "/Library/Frameworks/Python.framework/Versions/7.3/lib/python2.7/site-packages/ScriptTest-1.2-py2.7.egg/scripttest/__init__.py", line 237, in run
    env=clean_environ(self.environ))
  File "/Library/Frameworks/Python.framework/Versions/7.3/lib/python2.7/subprocess.py", line 679, in __init__
    errread, errwrite)
  File "/Library/Frameworks/Python.framework/Versions/7.3/lib/python2.7/subprocess.py", line 1249, in _execute_child
    raise child_exception

test orientation_magic.py: [Errno 2] No such file or directory.  
Traceback below: 
  File "/Users/nebula/Python/PmagPy/Command_line_Tests/error_logging.py", line 27, in go_through
    v()
  File "Extra_output.py", line 342, in complete_orientation_magic_test
    orientation_magic.ex_out_sequence()
  File "Extra_output.py", line 139, in ex_out_sequence
    self.run_program()
  File "Extra_output.py", line 63, in run_program
    obj = env.run(self.name, '-WD', directory, '-f', self.infile, self.tag1, self.outfile1, self.tag2, self.outfile2, self.arg1, self.arg2, self.arg3, self.arg4, stdin=self.stdin)
  File "/Library/Frameworks/Python.framework/Versions/7.3/lib/python2.7/site-packages/ScriptTest-1.2-py2.7.egg/scripttest/__init__.py", line 237, in run
    env=clean_environ(self.environ))
  File "/Library/Frameworks/Python.framework/Versions/7.3/lib/python2.7/subprocess.py", line 679, in __init__
    errread, errwrite)
  File "/Library/Frameworks/Python.framework/Versions/7.3/lib/python2.7/subprocess.py", line 1249, in _execute_child
    raise child_exception

programs with errors: ['test hysteresis_magic.py', 'test IODP_csv.py', None, 'test pmag_results_extract.py', 'test parse_measurements_test()', None, 'test thellier_magic_redo.py', 'test kly4s_magic.py', 'test CIT_magic.py', 'test k15_magic.py', None, 'testing aarm_magic.py', 'test atrm_magic.py', 'test orientation_magic.py']

