extra_output_errors_list:  
test IODP_csv.py: Wrong output -- output list did not match correct_output_list -- running IODP_csv_magic.py.  
Traceback below: 
  File "/Users/nebula/Python/PmagPy/Command_line_Tests/error_logging.py", line 27, in go_through
    v()
  File "Extra_output.py", line 439, in complete_IODP_csv_magic_test
    IODP_csv.check_file_output(out3, ref3, "correct")
  File "Extra_output.py", line 135, in check_file_output
    self.check_list_output(out, ref)
  File "Extra_output.py", line 93, in check_list_output
    raise NameError("Wrong output -- output list did not match correct_output_list -- running " + str(self.name))

programs with errors: ['test IODP_csv.py']

