bootstrap_errors_list:  
test watsonsV.py: [Errno 2] No such file or directory.  
Traceback below: 
  File "/Users/nebula/Python/PmagPy/Command_line_Tests/error_logging.py", line 27, in go_through
    v()
  File "Bootstrap.py", line 130, in complete_watsonsV_test
    output1 = do_watsonsV()
  File "Bootstrap.py", line 118, in do_watsonsV
    obj = env.run("watsonsV.py", "-f", watsonsV_infile, "-f2", watsonsV_infile2, stdin='q')
  File "/Library/Frameworks/Python.framework/Versions/7.3/lib/python2.7/site-packages/ScriptTest-1.2-py2.7.egg/scripttest/__init__.py", line 237, in run
    env=clean_environ(self.environ))
  File "/Library/Frameworks/Python.framework/Versions/7.3/lib/python2.7/subprocess.py", line 679, in __init__
    errread, errwrite)
  File "/Library/Frameworks/Python.framework/Versions/7.3/lib/python2.7/subprocess.py", line 1249, in _execute_child
    raise child_exception

test eqarea_magic.py: [Errno 2] No such file or directory.  
Traceback below: 
  File "/Users/nebula/Python/PmagPy/Command_line_Tests/error_logging.py", line 27, in go_through
    v()
  File "Bootstrap.py", line 185, in complete_eqarea_magic_test
    obj = env.run('eqarea_magic.py', '-WD', directory, '-f', eqarea_magic_infile, '-obj', 'loc', '-crd', 'g', '-ell', 'Be', stdin='q')
  File "/Library/Frameworks/Python.framework/Versions/7.3/lib/python2.7/site-packages/ScriptTest-1.2-py2.7.egg/scripttest/__init__.py", line 237, in run
    env=clean_environ(self.environ))
  File "/Library/Frameworks/Python.framework/Versions/7.3/lib/python2.7/subprocess.py", line 679, in __init__
    errread, errwrite)
  File "/Library/Frameworks/Python.framework/Versions/7.3/lib/python2.7/subprocess.py", line 1249, in _execute_child
    raise child_exception

test scalc_magic.py: [Errno 2] No such file or directory.  
Traceback below: 
  File "/Users/nebula/Python/PmagPy/Command_line_Tests/error_logging.py", line 27, in go_through
    v()
  File "Bootstrap.py", line 89, in complete_scalc_magic_test
    output = do_scalc_magic()
  File "Bootstrap.py", line 79, in do_scalc_magic
    obj = env.run('scalc_magic.py', '-f', file_prefix + 'scalc_magic_example.txt', '-v', '-b')
  File "/Library/Frameworks/Python.framework/Versions/7.3/lib/python2.7/site-packages/ScriptTest-1.2-py2.7.egg/scripttest/__init__.py", line 237, in run
    env=clean_environ(self.environ))
  File "/Library/Frameworks/Python.framework/Versions/7.3/lib/python2.7/subprocess.py", line 679, in __init__
    errread, errwrite)
  File "/Library/Frameworks/Python.framework/Versions/7.3/lib/python2.7/subprocess.py", line 1249, in _execute_child
    raise child_exception

test find_EI.py: [Errno 2] No such file or directory.  
Traceback below: 
  File "/Users/nebula/Python/PmagPy/Command_line_Tests/error_logging.py", line 27, in go_through
    v()
  File "Bootstrap.py", line 153, in complete_find_EI_test
    output1 = run_EI(1000)
  File "Bootstrap.py", line 140, in run_EI
    obj = env.run('find_EI.py', '-f', file_prefix + 'find_EI_example.dat', '-nb', num, stdin='a')
  File "/Library/Frameworks/Python.framework/Versions/7.3/lib/python2.7/site-packages/ScriptTest-1.2-py2.7.egg/scripttest/__init__.py", line 237, in run
    env=clean_environ(self.environ))
  File "/Library/Frameworks/Python.framework/Versions/7.3/lib/python2.7/subprocess.py", line 679, in __init__
    errread, errwrite)
  File "/Library/Frameworks/Python.framework/Versions/7.3/lib/python2.7/subprocess.py", line 1249, in _execute_child
    raise child_exception

programs with errors: ['test watsonsV.py', 'test eqarea_magic.py', 'test scalc_magic.py', 'test find_EI.py']

rename_me_errors_list:  
test quick_hyst.py: [Errno 2] No such file or directory.  
Traceback below: 
  File "/Users/nebula/Python/PmagPy/Command_line_Tests/error_logging.py", line 27, in go_through
    v()
  File "Rename_me.py", line 1021, in complete_quick_hyst_test
    quick_hyst.plot_program_sequence(stdout=True)
  File "Rename_me.py", line 192, in plot_program_sequence
    self.test_help()
  File "Rename_me.py", line 161, in test_help
    obj = env.run(self.name, '-h')
  File "/Library/Frameworks/Python.framework/Versions/7.3/lib/python2.7/site-packages/ScriptTest-1.2-py2.7.egg/scripttest/__init__.py", line 237, in run
    env=clean_environ(self.environ))
  File "/Library/Frameworks/Python.framework/Versions/7.3/lib/python2.7/subprocess.py", line 679, in __init__
    errread, errwrite)
  File "/Library/Frameworks/Python.framework/Versions/7.3/lib/python2.7/subprocess.py", line 1249, in _execute_child
    raise child_exception

test magic_select.py: [Errno 2] No such file or directory.  
Traceback below: 
  File "/Users/nebula/Python/PmagPy/Command_line_Tests/error_logging.py", line 27, in go_through
    v()
  File "Rename_me.py", line 448, in complete_magic_select_test
    magic_select.file_in_file_out_sequence()
  File "Rename_me.py", line 183, in file_in_file_out_sequence
    self.test_help()
  File "Rename_me.py", line 161, in test_help
    obj = env.run(self.name, '-h')
  File "/Library/Frameworks/Python.framework/Versions/7.3/lib/python2.7/site-packages/ScriptTest-1.2-py2.7.egg/scripttest/__init__.py", line 237, in run
    env=clean_environ(self.environ))
  File "/Library/Frameworks/Python.framework/Versions/7.3/lib/python2.7/subprocess.py", line 679, in __init__
    errread, errwrite)
  File "/Library/Frameworks/Python.framework/Versions/7.3/lib/python2.7/subprocess.py", line 1249, in _execute_child
    raise child_exception

test irmaq_magic.py: [Errno 2] No such file or directory.  
Traceback below: 
  File "/Users/nebula/Python/PmagPy/Command_line_Tests/error_logging.py", line 27, in go_through
    v()
  File "Rename_me.py", line 915, in complete_irmaq_magic_test
    irmaq_magic.plot_program_sequence(stdout=False)
  File "Rename_me.py", line 192, in plot_program_sequence
    self.test_help()
  File "Rename_me.py", line 161, in test_help
    obj = env.run(self.name, '-h')
  File "/Library/Frameworks/Python.framework/Versions/7.3/lib/python2.7/site-packages/ScriptTest-1.2-py2.7.egg/scripttest/__init__.py", line 237, in run
    env=clean_environ(self.environ))
  File "/Library/Frameworks/Python.framework/Versions/7.3/lib/python2.7/subprocess.py", line 679, in __init__
    errread, errwrite)
  File "/Library/Frameworks/Python.framework/Versions/7.3/lib/python2.7/subprocess.py", line 1249, in _execute_child
    raise child_exception

test igrf.py: small change in output files.  someone else must debug.  
Traceback below: 
  File "/Users/nebula/Python/PmagPy/Command_line_Tests/error_logging.py", line 27, in go_through
    v()
  File "Rename_me.py", line 647, in complete_igrf_test
    raise Exception('small change in output files.  someone else must debug')

test zeq.py: [Errno 2] No such file or directory.  
Traceback below: 
  File "/Users/nebula/Python/PmagPy/Command_line_Tests/error_logging.py", line 27, in go_through
    v()
  File "Rename_me.py", line 280, in complete_zeq_test
    zeq.plot_program_sequence(stdout=True)
  File "Rename_me.py", line 192, in plot_program_sequence
    self.test_help()
  File "Rename_me.py", line 161, in test_help
    obj = env.run(self.name, '-h')
  File "/Library/Frameworks/Python.framework/Versions/7.3/lib/python2.7/site-packages/ScriptTest-1.2-py2.7.egg/scripttest/__init__.py", line 237, in run
    env=clean_environ(self.environ))
  File "/Library/Frameworks/Python.framework/Versions/7.3/lib/python2.7/subprocess.py", line 679, in __init__
    errread, errwrite)
  File "/Library/Frameworks/Python.framework/Versions/7.3/lib/python2.7/subprocess.py", line 1249, in _execute_child
    raise child_exception

test upload_magic.py: [Errno 2] No such file or directory.  
Traceback below: 
  File "/Users/nebula/Python/PmagPy/Command_line_Tests/error_logging.py", line 27, in go_through
    v()
  File "Rename_me.py", line 1143, in complete_upload_magic_test
    obj = env.run("upload_magic.py", cwd=directory + "/upload_magic") # cwd allows specifying a directory other than the one you are in
  File "/Library/Frameworks/Python.framework/Versions/7.3/lib/python2.7/site-packages/ScriptTest-1.2-py2.7.egg/scripttest/__init__.py", line 237, in run
    env=clean_environ(self.environ))
  File "/Library/Frameworks/Python.framework/Versions/7.3/lib/python2.7/subprocess.py", line 679, in __init__
    errread, errwrite)
  File "/Library/Frameworks/Python.framework/Versions/7.3/lib/python2.7/subprocess.py", line 1249, in _execute_child
    raise child_exception

test_watsonsF.py: [Errno 2] No such file or directory.  
Traceback below: 
  File "/Users/nebula/Python/PmagPy/Command_line_Tests/error_logging.py", line 27, in go_through
    v()
  File "Rename_me.py", line 559, in complete_watsonsF_test
    watsonsF.list_sequence()
  File "Rename_me.py", line 203, in list_sequence
    result = self.run_program(output_type = "stdout")
  File "Rename_me.py", line 83, in run_program
    obj = env.run(self.name, '-f', self.infile, '-F', self.outfile, self.arg_0, self.arg_1, self.arg_2, self.arg_3, self.arg_4, self.arg_5, stdin=self.stdin)
  File "/Library/Frameworks/Python.framework/Versions/7.3/lib/python2.7/site-packages/ScriptTest-1.2-py2.7.egg/scripttest/__init__.py", line 237, in run
    env=clean_environ(self.environ))
  File "/Library/Frameworks/Python.framework/Versions/7.3/lib/python2.7/subprocess.py", line 679, in __init__
    errread, errwrite)
  File "/Library/Frameworks/Python.framework/Versions/7.3/lib/python2.7/subprocess.py", line 1249, in _execute_child
    raise child_exception

test b_vdm.py: [Errno 2] No such file or directory.  
Traceback below: 
  File "/Users/nebula/Python/PmagPy/Command_line_Tests/error_logging.py", line 27, in go_through
    v()
  File "Rename_me.py", line 571, in complete_b_vdm_test
    b_vdm.file_in_file_out_sequence(interactive=True)
  File "Rename_me.py", line 183, in file_in_file_out_sequence
    self.test_help()
  File "Rename_me.py", line 161, in test_help
    obj = env.run(self.name, '-h')
  File "/Library/Frameworks/Python.framework/Versions/7.3/lib/python2.7/site-packages/ScriptTest-1.2-py2.7.egg/scripttest/__init__.py", line 237, in run
    env=clean_environ(self.environ))
  File "/Library/Frameworks/Python.framework/Versions/7.3/lib/python2.7/subprocess.py", line 679, in __init__
    errread, errwrite)
  File "/Library/Frameworks/Python.framework/Versions/7.3/lib/python2.7/subprocess.py", line 1249, in _execute_child
    raise child_exception

test s_hext.py: [Errno 2] No such file or directory.  
Traceback below: 
  File "/Users/nebula/Python/PmagPy/Command_line_Tests/error_logging.py", line 27, in go_through
    v()
  File "Rename_me.py", line 538, in complete_s_hext_test
    s_hext.list_sequence()
  File "Rename_me.py", line 203, in list_sequence
    result = self.run_program(output_type = "stdout")
  File "Rename_me.py", line 83, in run_program
    obj = env.run(self.name, '-f', self.infile, '-F', self.outfile, self.arg_0, self.arg_1, self.arg_2, self.arg_3, self.arg_4, self.arg_5, stdin=self.stdin)
  File "/Library/Frameworks/Python.framework/Versions/7.3/lib/python2.7/site-packages/ScriptTest-1.2-py2.7.egg/scripttest/__init__.py", line 237, in run
    env=clean_environ(self.environ))
  File "/Library/Frameworks/Python.framework/Versions/7.3/lib/python2.7/subprocess.py", line 679, in __init__
    errread, errwrite)
  File "/Library/Frameworks/Python.framework/Versions/7.3/lib/python2.7/subprocess.py", line 1249, in _execute_child
    raise child_exception

test_plotXY.py: [Errno 2] No such file or directory.  
Traceback below: 
  File "/Users/nebula/Python/PmagPy/Command_line_Tests/error_logging.py", line 27, in go_through
    v()
  File "Rename_me.py", line 984, in complete_plotxy_test
    plotxy.plot_program_sequence(stdout=False)
  File "Rename_me.py", line 192, in plot_program_sequence
    self.test_help()
  File "Rename_me.py", line 161, in test_help
    obj = env.run(self.name, '-h')
  File "/Library/Frameworks/Python.framework/Versions/7.3/lib/python2.7/site-packages/ScriptTest-1.2-py2.7.egg/scripttest/__init__.py", line 237, in run
    env=clean_environ(self.environ))
  File "/Library/Frameworks/Python.framework/Versions/7.3/lib/python2.7/subprocess.py", line 679, in __init__
    errread, errwrite)
  File "/Library/Frameworks/Python.framework/Versions/7.3/lib/python2.7/subprocess.py", line 1249, in _execute_child
    raise child_exception

test pca_example.py: [Errno 2] No such file or directory.  
Traceback below: 
  File "/Users/nebula/Python/PmagPy/Command_line_Tests/error_logging.py", line 27, in go_through
    v()
  File "Rename_me.py", line 481, in complete_pca_test
    pca.list_sequence()
  File "Rename_me.py", line 203, in list_sequence
    result = self.run_program(output_type = "stdout")
  File "Rename_me.py", line 83, in run_program
    obj = env.run(self.name, '-f', self.infile, '-F', self.outfile, self.arg_0, self.arg_1, self.arg_2, self.arg_3, self.arg_4, self.arg_5, stdin=self.stdin)
  File "/Library/Frameworks/Python.framework/Versions/7.3/lib/python2.7/site-packages/ScriptTest-1.2-py2.7.egg/scripttest/__init__.py", line 237, in run
    env=clean_environ(self.environ))
  File "/Library/Frameworks/Python.framework/Versions/7.3/lib/python2.7/subprocess.py", line 679, in __init__
    errread, errwrite)
  File "/Library/Frameworks/Python.framework/Versions/7.3/lib/python2.7/subprocess.py", line 1249, in _execute_child
    raise child_exception

test plotdi_a.py: [Errno 2] No such file or directory.  
Traceback below: 
  File "/Users/nebula/Python/PmagPy/Command_line_Tests/error_logging.py", line 27, in go_through
    v()
  File "Rename_me.py", line 975, in complete_plotdi_a_test
    plotdi_a.plot_program_sequence(stdout=False)
  File "Rename_me.py", line 192, in plot_program_sequence
    self.test_help()
  File "Rename_me.py", line 161, in test_help
    obj = env.run(self.name, '-h')
  File "/Library/Frameworks/Python.framework/Versions/7.3/lib/python2.7/site-packages/ScriptTest-1.2-py2.7.egg/scripttest/__init__.py", line 237, in run
    env=clean_environ(self.environ))
  File "/Library/Frameworks/Python.framework/Versions/7.3/lib/python2.7/subprocess.py", line 679, in __init__
    errread, errwrite)
  File "/Library/Frameworks/Python.framework/Versions/7.3/lib/python2.7/subprocess.py", line 1249, in _execute_child
    raise child_exception

test sio_magic.py: [Errno 2] No such file or directory.  
Traceback below: 
  File "/Users/nebula/Python/PmagPy/Command_line_Tests/error_logging.py", line 27, in go_through
    v()
  File "Rename_me.py", line 1253, in complete_sio_magic_test
    sio_magic.file_in_file_out_sequence()
  File "Rename_me.py", line 183, in file_in_file_out_sequence
    self.test_help()
  File "Rename_me.py", line 161, in test_help
    obj = env.run(self.name, '-h')
  File "/Library/Frameworks/Python.framework/Versions/7.3/lib/python2.7/site-packages/ScriptTest-1.2-py2.7.egg/scripttest/__init__.py", line 237, in run
    env=clean_environ(self.environ))
  File "/Library/Frameworks/Python.framework/Versions/7.3/lib/python2.7/subprocess.py", line 679, in __init__
    errread, errwrite)
  File "/Library/Frameworks/Python.framework/Versions/7.3/lib/python2.7/subprocess.py", line 1249, in _execute_child
    raise child_exception

test foldtest.py: [Errno 2] No such file or directory.  
Traceback below: 
  File "/Users/nebula/Python/PmagPy/Command_line_Tests/error_logging.py", line 27, in go_through
    v()
  File "Rename_me.py", line 895, in complete_foldtest_test
    foldtest.plot_program_sequence(stdout=False)
  File "Rename_me.py", line 192, in plot_program_sequence
    self.test_help()
  File "Rename_me.py", line 161, in test_help
    obj = env.run(self.name, '-h')
  File "/Library/Frameworks/Python.framework/Versions/7.3/lib/python2.7/site-packages/ScriptTest-1.2-py2.7.egg/scripttest/__init__.py", line 237, in run
    env=clean_environ(self.environ))
  File "/Library/Frameworks/Python.framework/Versions/7.3/lib/python2.7/subprocess.py", line 679, in __init__
    errread, errwrite)
  File "/Library/Frameworks/Python.framework/Versions/7.3/lib/python2.7/subprocess.py", line 1249, in _execute_child
    raise child_exception

test s_geo.py: [Errno 2] No such file or directory.  
Traceback below: 
  File "/Users/nebula/Python/PmagPy/Command_line_Tests/error_logging.py", line 27, in go_through
    v()
  File "Rename_me.py", line 698, in complete_s_geo_test
    s_geo.file_in_file_out_sequence()
  File "Rename_me.py", line 183, in file_in_file_out_sequence
    self.test_help()
  File "Rename_me.py", line 161, in test_help
    obj = env.run(self.name, '-h')
  File "/Library/Frameworks/Python.framework/Versions/7.3/lib/python2.7/site-packages/ScriptTest-1.2-py2.7.egg/scripttest/__init__.py", line 237, in run
    env=clean_environ(self.environ))
  File "/Library/Frameworks/Python.framework/Versions/7.3/lib/python2.7/subprocess.py", line 679, in __init__
    errread, errwrite)
  File "/Library/Frameworks/Python.framework/Versions/7.3/lib/python2.7/subprocess.py", line 1249, in _execute_child
    raise child_exception

test make_magic_plots.py: [Errno 2] No such file or directory.  
Traceback below: 
  File "/Users/nebula/Python/PmagPy/Command_line_Tests/error_logging.py", line 27, in go_through
    v()
  File "Rename_me.py", line 1154, in complete_make_magic_plots_test
    obj = env.run("make_magic_plots.py", cwd=directory + "/make_magic_plots_example")
  File "/Library/Frameworks/Python.framework/Versions/7.3/lib/python2.7/site-packages/ScriptTest-1.2-py2.7.egg/scripttest/__init__.py", line 237, in run
    env=clean_environ(self.environ))
  File "/Library/Frameworks/Python.framework/Versions/7.3/lib/python2.7/subprocess.py", line 679, in __init__
    errread, errwrite)
  File "/Library/Frameworks/Python.framework/Versions/7.3/lib/python2.7/subprocess.py", line 1249, in _execute_child
    raise child_exception

test dir_cart.py: [Errno 2] No such file or directory.  
Traceback below: 
  File "/Users/nebula/Python/PmagPy/Command_line_Tests/error_logging.py", line 27, in go_through
    v()
  File "Rename_me.py", line 602, in complete_dir_cart_test
    dir_cart.file_in_file_out_sequence(interactive=True)
  File "Rename_me.py", line 183, in file_in_file_out_sequence
    self.test_help()
  File "Rename_me.py", line 161, in test_help
    obj = env.run(self.name, '-h')
  File "/Library/Frameworks/Python.framework/Versions/7.3/lib/python2.7/site-packages/ScriptTest-1.2-py2.7.egg/scripttest/__init__.py", line 237, in run
    env=clean_environ(self.environ))
  File "/Library/Frameworks/Python.framework/Versions/7.3/lib/python2.7/subprocess.py", line 679, in __init__
    errread, errwrite)
  File "/Library/Frameworks/Python.framework/Versions/7.3/lib/python2.7/subprocess.py", line 1249, in _execute_child
    raise child_exception

test chi_magic.py: [Errno 2] No such file or directory.  
Traceback below: 
  File "/Users/nebula/Python/PmagPy/Command_line_Tests/error_logging.py", line 27, in go_through
    v()
  File "Rename_me.py", line 790, in complete_chi_magic_test
    chi_magic.plot_program_sequence(stdout=False)
  File "Rename_me.py", line 192, in plot_program_sequence
    self.test_help()
  File "Rename_me.py", line 161, in test_help
    obj = env.run(self.name, '-h')
  File "/Library/Frameworks/Python.framework/Versions/7.3/lib/python2.7/site-packages/ScriptTest-1.2-py2.7.egg/scripttest/__init__.py", line 237, in run
    env=clean_environ(self.environ))
  File "/Library/Frameworks/Python.framework/Versions/7.3/lib/python2.7/subprocess.py", line 679, in __init__
    errread, errwrite)
  File "/Library/Frameworks/Python.framework/Versions/7.3/lib/python2.7/subprocess.py", line 1249, in _execute_child
    raise child_exception

test qqplot.py: [Errno 2] No such file or directory.  
Traceback below: 
  File "/Users/nebula/Python/PmagPy/Command_line_Tests/error_logging.py", line 27, in go_through
    v()
  File "Rename_me.py", line 993, in complete_qqplot_test
    qqplot_output = qqplot.run_program(output_type='stdout')
  File "Rename_me.py", line 83, in run_program
    obj = env.run(self.name, '-f', self.infile, '-F', self.outfile, self.arg_0, self.arg_1, self.arg_2, self.arg_3, self.arg_4, self.arg_5, stdin=self.stdin)
  File "/Library/Frameworks/Python.framework/Versions/7.3/lib/python2.7/site-packages/ScriptTest-1.2-py2.7.egg/scripttest/__init__.py", line 237, in run
    env=clean_environ(self.environ))
  File "/Library/Frameworks/Python.framework/Versions/7.3/lib/python2.7/subprocess.py", line 679, in __init__
    errread, errwrite)
  File "/Library/Frameworks/Python.framework/Versions/7.3/lib/python2.7/subprocess.py", line 1249, in _execute_child
    raise child_exception

weird ani_depthplot_test: [Errno 2] No such file or directory.  
Traceback below: 
  File "/Users/nebula/Python/PmagPy/Command_line_Tests/error_logging.py", line 27, in go_through
    v()
  File "Rename_me.py", line 757, in weird_ani_depthplot_test
    obj = env.run('ani_depthplot.py', '-WD', directory, '-f', ani_depthplot_infile, '-f', ani_depthplot_outfile, '-fsa', ani_depthplot_fsa, stdin = 'a')
  File "/Library/Frameworks/Python.framework/Versions/7.3/lib/python2.7/site-packages/ScriptTest-1.2-py2.7.egg/scripttest/__init__.py", line 237, in run
    env=clean_environ(self.environ))
  File "/Library/Frameworks/Python.framework/Versions/7.3/lib/python2.7/subprocess.py", line 679, in __init__
    errread, errwrite)
  File "/Library/Frameworks/Python.framework/Versions/7.3/lib/python2.7/subprocess.py", line 1249, in _execute_child
    raise child_exception

test measurements_normalize_test.py: [Errno 2] No such file or directory.  
Traceback below: 
  File "/Users/nebula/Python/PmagPy/Command_line_Tests/error_logging.py", line 27, in go_through
    v()
  File "Rename_me.py", line 1205, in complete_measurements_normalize_test
    measurements_normalize.file_in_file_out_sequence()
  File "Rename_me.py", line 183, in file_in_file_out_sequence
    self.test_help()
  File "Rename_me.py", line 161, in test_help
    obj = env.run(self.name, '-h')
  File "/Library/Frameworks/Python.framework/Versions/7.3/lib/python2.7/site-packages/ScriptTest-1.2-py2.7.egg/scripttest/__init__.py", line 237, in run
    env=clean_environ(self.environ))
  File "/Library/Frameworks/Python.framework/Versions/7.3/lib/python2.7/subprocess.py", line 679, in __init__
    errread, errwrite)
  File "/Library/Frameworks/Python.framework/Versions/7.3/lib/python2.7/subprocess.py", line 1249, in _execute_child
    raise child_exception

test go_princ.py: [Errno 2] No such file or directory.  
Traceback below: 
  File "/Users/nebula/Python/PmagPy/Command_line_Tests/error_logging.py", line 27, in go_through
    v()
  File "Rename_me.py", line 643, in complete_goprinc_test
    goprinc.file_in_file_out_sequence()
  File "Rename_me.py", line 183, in file_in_file_out_sequence
    self.test_help()
  File "Rename_me.py", line 161, in test_help
    obj = env.run(self.name, '-h')
  File "/Library/Frameworks/Python.framework/Versions/7.3/lib/python2.7/site-packages/ScriptTest-1.2-py2.7.egg/scripttest/__init__.py", line 237, in run
    env=clean_environ(self.environ))
  File "/Library/Frameworks/Python.framework/Versions/7.3/lib/python2.7/subprocess.py", line 679, in __init__
    errread, errwrite)
  File "/Library/Frameworks/Python.framework/Versions/7.3/lib/python2.7/subprocess.py", line 1249, in _execute_child
    raise child_exception

test pt_rot.py: [Errno 2] No such file or directory.  
Traceback below: 
  File "/Users/nebula/Python/PmagPy/Command_line_Tests/error_logging.py", line 27, in go_through
    v()
  File "Rename_me.py", line 378, in complete_pt_rot_test
    pt_rot.file_in_file_out_sequence()
  File "Rename_me.py", line 183, in file_in_file_out_sequence
    self.test_help()
  File "Rename_me.py", line 161, in test_help
    obj = env.run(self.name, '-h')
  File "/Library/Frameworks/Python.framework/Versions/7.3/lib/python2.7/site-packages/ScriptTest-1.2-py2.7.egg/scripttest/__init__.py", line 237, in run
    env=clean_environ(self.environ))
  File "/Library/Frameworks/Python.framework/Versions/7.3/lib/python2.7/subprocess.py", line 679, in __init__
    errread, errwrite)
  File "/Library/Frameworks/Python.framework/Versions/7.3/lib/python2.7/subprocess.py", line 1249, in _execute_child
    raise child_exception

test tdt_magic.py: TDT_magic pull up gui window and can not be tested.  
Traceback below: 
  File "/Users/nebula/Python/PmagPy/Command_line_Tests/error_logging.py", line 27, in go_through
    v()
  File "Rename_me.py", line 1271, in complete_TDT_magic_test
    raise Exception('TDT_magic pull up gui window and can not be tested')

test dayplot_magic.py: [Errno 2] No such file or directory.  
Traceback below: 
  File "/Users/nebula/Python/PmagPy/Command_line_Tests/error_logging.py", line 27, in go_through
    v()
  File "Rename_me.py", line 826, in complete_dayplot_magic_test
    dayplot_magic.plot_program_sequence(stdout=False)
  File "Rename_me.py", line 192, in plot_program_sequence
    self.test_help()
  File "Rename_me.py", line 161, in test_help
    obj = env.run(self.name, '-h')
  File "/Library/Frameworks/Python.framework/Versions/7.3/lib/python2.7/site-packages/ScriptTest-1.2-py2.7.egg/scripttest/__init__.py", line 237, in run
    env=clean_environ(self.environ))
  File "/Library/Frameworks/Python.framework/Versions/7.3/lib/python2.7/subprocess.py", line 679, in __init__
    errread, errwrite)
  File "/Library/Frameworks/Python.framework/Versions/7.3/lib/python2.7/subprocess.py", line 1249, in _execute_child
    raise child_exception

test s_eigs.py: [Errno 2] No such file or directory.  
Traceback below: 
  File "/Users/nebula/Python/PmagPy/Command_line_Tests/error_logging.py", line 27, in go_through
    v()
  File "Rename_me.py", line 693, in complete_s_eigs_test
    s_eigs.file_in_file_out_sequence()
  File "Rename_me.py", line 183, in file_in_file_out_sequence
    self.test_help()
  File "Rename_me.py", line 161, in test_help
    obj = env.run(self.name, '-h')
  File "/Library/Frameworks/Python.framework/Versions/7.3/lib/python2.7/site-packages/ScriptTest-1.2-py2.7.egg/scripttest/__init__.py", line 237, in run
    env=clean_environ(self.environ))
  File "/Library/Frameworks/Python.framework/Versions/7.3/lib/python2.7/subprocess.py", line 679, in __init__
    errread, errwrite)
  File "/Library/Frameworks/Python.framework/Versions/7.3/lib/python2.7/subprocess.py", line 1249, in _execute_child
    raise child_exception

test lowrie_magic.py: [Errno 2] No such file or directory.  
Traceback below: 
  File "/Users/nebula/Python/PmagPy/Command_line_Tests/error_logging.py", line 27, in go_through
    v()
  File "Rename_me.py", line 954, in complete_lowrie_magic_test
    lowrie_magic.plot_program_sequence(stdout=True)
  File "Rename_me.py", line 192, in plot_program_sequence
    self.test_help()
  File "Rename_me.py", line 161, in test_help
    obj = env.run(self.name, '-h')
  File "/Library/Frameworks/Python.framework/Versions/7.3/lib/python2.7/site-packages/ScriptTest-1.2-py2.7.egg/scripttest/__init__.py", line 237, in run
    env=clean_environ(self.environ))
  File "/Library/Frameworks/Python.framework/Versions/7.3/lib/python2.7/subprocess.py", line 679, in __init__
    errread, errwrite)
  File "/Library/Frameworks/Python.framework/Versions/7.3/lib/python2.7/subprocess.py", line 1249, in _execute_child
    raise child_exception

test incfish.py: [Errno 2] No such file or directory.  
Traceback below: 
  File "/Users/nebula/Python/PmagPy/Command_line_Tests/error_logging.py", line 27, in go_through
    v()
  File "Rename_me.py", line 439, in complete_incfish_test
    incfish.file_in_file_out_sequence()
  File "Rename_me.py", line 183, in file_in_file_out_sequence
    self.test_help()
  File "Rename_me.py", line 161, in test_help
    obj = env.run(self.name, '-h')
  File "/Library/Frameworks/Python.framework/Versions/7.3/lib/python2.7/site-packages/ScriptTest-1.2-py2.7.egg/scripttest/__init__.py", line 237, in run
    env=clean_environ(self.environ))
  File "/Library/Frameworks/Python.framework/Versions/7.3/lib/python2.7/subprocess.py", line 679, in __init__
    errread, errwrite)
  File "/Library/Frameworks/Python.framework/Versions/7.3/lib/python2.7/subprocess.py", line 1249, in _execute_child
    raise child_exception

test_basemap_magic.py: [Errno 2] No such file or directory.  
Traceback below: 
  File "/Users/nebula/Python/PmagPy/Command_line_Tests/error_logging.py", line 27, in go_through
    v()
  File "Rename_me.py", line 767, in complete_basemap_magic_test
    basemap_magic.plot_program_sequence(stdout=False)
  File "Rename_me.py", line 192, in plot_program_sequence
    self.test_help()
  File "Rename_me.py", line 161, in test_help
    obj = env.run(self.name, '-h')
  File "/Library/Frameworks/Python.framework/Versions/7.3/lib/python2.7/site-packages/ScriptTest-1.2-py2.7.egg/scripttest/__init__.py", line 237, in run
    env=clean_environ(self.environ))
  File "/Library/Frameworks/Python.framework/Versions/7.3/lib/python2.7/subprocess.py", line 679, in __init__
    errread, errwrite)
  File "/Library/Frameworks/Python.framework/Versions/7.3/lib/python2.7/subprocess.py", line 1249, in _execute_child
    raise child_exception

test nrm_specimens_magic.py: [Errno 2] No such file or directory.  
Traceback below: 
  File "/Users/nebula/Python/PmagPy/Command_line_Tests/error_logging.py", line 27, in go_through
    v()
  File "Rename_me.py", line 460, in complete_nrm_specimens_magic_test
    nrm_specimens_magic.file_in_file_out_sequence()
  File "Rename_me.py", line 183, in file_in_file_out_sequence
    self.test_help()
  File "Rename_me.py", line 161, in test_help
    obj = env.run(self.name, '-h')
  File "/Library/Frameworks/Python.framework/Versions/7.3/lib/python2.7/site-packages/ScriptTest-1.2-py2.7.egg/scripttest/__init__.py", line 237, in run
    env=clean_environ(self.environ))
  File "/Library/Frameworks/Python.framework/Versions/7.3/lib/python2.7/subprocess.py", line 679, in __init__
    errread, errwrite)
  File "/Library/Frameworks/Python.framework/Versions/7.3/lib/python2.7/subprocess.py", line 1249, in _execute_child
    raise child_exception

test di_eq.py: [Errno 2] No such file or directory.  
Traceback below: 
  File "/Users/nebula/Python/PmagPy/Command_line_Tests/error_logging.py", line 27, in go_through
    v()
  File "Rename_me.py", line 302, in complete_di_eq_test
    di_eq.list_sequence()
  File "Rename_me.py", line 203, in list_sequence
    result = self.run_program(output_type = "stdout")
  File "Rename_me.py", line 83, in run_program
    obj = env.run(self.name, '-f', self.infile, '-F', self.outfile, self.arg_0, self.arg_1, self.arg_2, self.arg_3, self.arg_4, self.arg_5, stdin=self.stdin)
  File "/Library/Frameworks/Python.framework/Versions/7.3/lib/python2.7/site-packages/ScriptTest-1.2-py2.7.egg/scripttest/__init__.py", line 237, in run
    env=clean_environ(self.environ))
  File "/Library/Frameworks/Python.framework/Versions/7.3/lib/python2.7/subprocess.py", line 679, in __init__
    errread, errwrite)
  File "/Library/Frameworks/Python.framework/Versions/7.3/lib/python2.7/subprocess.py", line 1249, in _execute_child
    raise child_exception

test cont_rot.py: [Errno 2] No such file or directory.  
Traceback below: 
  File "/Users/nebula/Python/PmagPy/Command_line_Tests/error_logging.py", line 27, in go_through
    v()
  File "Rename_me.py", line 338, in complete_cont_rot_test
    obj = env.run('cont_rot.py', '-con', 'af:sam', '-prj', 'ortho', '-eye', '-20', '0', '-sym', 'k-', '1', '-age', '180', '-res', 'l', stdin='a')
  File "/Library/Frameworks/Python.framework/Versions/7.3/lib/python2.7/site-packages/ScriptTest-1.2-py2.7.egg/scripttest/__init__.py", line 237, in run
    env=clean_environ(self.environ))
  File "/Library/Frameworks/Python.framework/Versions/7.3/lib/python2.7/subprocess.py", line 679, in __init__
    errread, errwrite)
  File "/Library/Frameworks/Python.framework/Versions/7.3/lib/python2.7/subprocess.py", line 1249, in _execute_child
    raise child_exception

test azdip_magic.py: [Errno 2] No such file or directory.  
Traceback below: 
  File "/Users/nebula/Python/PmagPy/Command_line_Tests/error_logging.py", line 27, in go_through
    v()
  File "Rename_me.py", line 315, in complete_azdip_magic_test
    azdip_magic.run_program(output_type='file')
  File "Rename_me.py", line 83, in run_program
    obj = env.run(self.name, '-f', self.infile, '-F', self.outfile, self.arg_0, self.arg_1, self.arg_2, self.arg_3, self.arg_4, self.arg_5, stdin=self.stdin)
  File "/Library/Frameworks/Python.framework/Versions/7.3/lib/python2.7/site-packages/ScriptTest-1.2-py2.7.egg/scripttest/__init__.py", line 237, in run
    env=clean_environ(self.environ))
  File "/Library/Frameworks/Python.framework/Versions/7.3/lib/python2.7/subprocess.py", line 679, in __init__
    errread, errwrite)
  File "/Library/Frameworks/Python.framework/Versions/7.3/lib/python2.7/subprocess.py", line 1249, in _execute_child
    raise child_exception

test stats.py: [Errno 2] No such file or directory.  
Traceback below: 
  File "/Users/nebula/Python/PmagPy/Command_line_Tests/error_logging.py", line 27, in go_through
    v()
  File "Rename_me.py", line 708, in complete_stats_test
    stats.file_in_file_out_sequence()
  File "Rename_me.py", line 183, in file_in_file_out_sequence
    self.test_help()
  File "Rename_me.py", line 161, in test_help
    obj = env.run(self.name, '-h')
  File "/Library/Frameworks/Python.framework/Versions/7.3/lib/python2.7/site-packages/ScriptTest-1.2-py2.7.egg/scripttest/__init__.py", line 237, in run
    env=clean_environ(self.environ))
  File "/Library/Frameworks/Python.framework/Versions/7.3/lib/python2.7/subprocess.py", line 679, in __init__
    errread, errwrite)
  File "/Library/Frameworks/Python.framework/Versions/7.3/lib/python2.7/subprocess.py", line 1249, in _execute_child
    raise child_exception

test scalc.py: [Errno 2] No such file or directory.  
Traceback below: 
  File "/Users/nebula/Python/PmagPy/Command_line_Tests/error_logging.py", line 27, in go_through
    v()
  File "Rename_me.py", line 492, in complete_scalc_test
    scalc.list_sequence()
  File "Rename_me.py", line 203, in list_sequence
    result = self.run_program(output_type = "stdout")
  File "Rename_me.py", line 83, in run_program
    obj = env.run(self.name, '-f', self.infile, '-F', self.outfile, self.arg_0, self.arg_1, self.arg_2, self.arg_3, self.arg_4, self.arg_5, stdin=self.stdin)
  File "/Library/Frameworks/Python.framework/Versions/7.3/lib/python2.7/site-packages/ScriptTest-1.2-py2.7.egg/scripttest/__init__.py", line 237, in run
    env=clean_environ(self.environ))
  File "/Library/Frameworks/Python.framework/Versions/7.3/lib/python2.7/subprocess.py", line 679, in __init__
    errread, errwrite)
  File "/Library/Frameworks/Python.framework/Versions/7.3/lib/python2.7/subprocess.py", line 1249, in _execute_child
    raise child_exception

test fishqq.py: [Errno 2] No such file or directory.  
Traceback below: 
  File "/Users/nebula/Python/PmagPy/Command_line_Tests/error_logging.py", line 27, in go_through
    v()
  File "Rename_me.py", line 874, in complete_fishqq_test
    fishqq.plot_program_sequence(stdout=False)
  File "Rename_me.py", line 192, in plot_program_sequence
    self.test_help()
  File "Rename_me.py", line 161, in test_help
    obj = env.run(self.name, '-h')
  File "/Library/Frameworks/Python.framework/Versions/7.3/lib/python2.7/site-packages/ScriptTest-1.2-py2.7.egg/scripttest/__init__.py", line 237, in run
    env=clean_environ(self.environ))
  File "/Library/Frameworks/Python.framework/Versions/7.3/lib/python2.7/subprocess.py", line 679, in __init__
    errread, errwrite)
  File "/Library/Frameworks/Python.framework/Versions/7.3/lib/python2.7/subprocess.py", line 1249, in _execute_child
    raise child_exception

test vector_mean.py: [Errno 2] No such file or directory.  
Traceback below: 
  File "/Users/nebula/Python/PmagPy/Command_line_Tests/error_logging.py", line 27, in go_through
    v()
  File "Rename_me.py", line 722, in complete_vector_mean_test
    vector_mean.file_in_file_out_sequence()
  File "Rename_me.py", line 183, in file_in_file_out_sequence
    self.test_help()
  File "Rename_me.py", line 161, in test_help
    obj = env.run(self.name, '-h')
  File "/Library/Frameworks/Python.framework/Versions/7.3/lib/python2.7/site-packages/ScriptTest-1.2-py2.7.egg/scripttest/__init__.py", line 237, in run
    env=clean_environ(self.environ))
  File "/Library/Frameworks/Python.framework/Versions/7.3/lib/python2.7/subprocess.py", line 679, in __init__
    errread, errwrite)
  File "/Library/Frameworks/Python.framework/Versions/7.3/lib/python2.7/subprocess.py", line 1249, in _execute_child
    raise child_exception

test revtest.py: [Errno 2] No such file or directory.  
Traceback below: 
  File "/Users/nebula/Python/PmagPy/Command_line_Tests/error_logging.py", line 27, in go_through
    v()
  File "Rename_me.py", line 1030, in complete_revtest_test
    revtest.plot_program_sequence(stdout=False)
  File "Rename_me.py", line 192, in plot_program_sequence
    self.test_help()
  File "Rename_me.py", line 161, in test_help
    obj = env.run(self.name, '-h')
  File "/Library/Frameworks/Python.framework/Versions/7.3/lib/python2.7/site-packages/ScriptTest-1.2-py2.7.egg/scripttest/__init__.py", line 237, in run
    env=clean_environ(self.environ))
  File "/Library/Frameworks/Python.framework/Versions/7.3/lib/python2.7/subprocess.py", line 679, in __init__
    errread, errwrite)
  File "/Library/Frameworks/Python.framework/Versions/7.3/lib/python2.7/subprocess.py", line 1249, in _execute_child
    raise child_exception

test combine_magic_test.py: [Errno 2] No such file or directory.  
Traceback below: 
  File "/Users/nebula/Python/PmagPy/Command_line_Tests/error_logging.py", line 27, in go_through
    v()
  File "Rename_me.py", line 328, in complete_combine_magic_test
    obj = env.run('combine_magic.py', '-WD', directory, '-F', output_file, '-f', input_1, input_2)
  File "/Library/Frameworks/Python.framework/Versions/7.3/lib/python2.7/site-packages/ScriptTest-1.2-py2.7.egg/scripttest/__init__.py", line 237, in run
    env=clean_environ(self.environ))
  File "/Library/Frameworks/Python.framework/Versions/7.3/lib/python2.7/subprocess.py", line 679, in __init__
    errread, errwrite)
  File "/Library/Frameworks/Python.framework/Versions/7.3/lib/python2.7/subprocess.py", line 1249, in _execute_child
    raise child_exception

test vdm_b.py: [Errno 2] No such file or directory.  
Traceback below: 
  File "/Users/nebula/Python/PmagPy/Command_line_Tests/error_logging.py", line 27, in go_through
    v()
  File "Rename_me.py", line 713, in complete_vdm_b_test
    vdm_b.file_in_file_out_sequence(interactive=True)
  File "Rename_me.py", line 183, in file_in_file_out_sequence
    self.test_help()
  File "Rename_me.py", line 161, in test_help
    obj = env.run(self.name, '-h')
  File "/Library/Frameworks/Python.framework/Versions/7.3/lib/python2.7/site-packages/ScriptTest-1.2-py2.7.egg/scripttest/__init__.py", line 237, in run
    env=clean_environ(self.environ))
  File "/Library/Frameworks/Python.framework/Versions/7.3/lib/python2.7/subprocess.py", line 679, in __init__
    errread, errwrite)
  File "/Library/Frameworks/Python.framework/Versions/7.3/lib/python2.7/subprocess.py", line 1249, in _execute_child
    raise child_exception

test biplot_magic.py: [Errno 2] No such file or directory.  
Traceback below: 
  File "/Users/nebula/Python/PmagPy/Command_line_Tests/error_logging.py", line 27, in go_through
    v()
  File "Rename_me.py", line 781, in complete_biplot_magic_test
    biplot_magic.plot_program_sequence(stdout=True)
  File "Rename_me.py", line 192, in plot_program_sequence
    self.test_help()
  File "Rename_me.py", line 161, in test_help
    obj = env.run(self.name, '-h')
  File "/Library/Frameworks/Python.framework/Versions/7.3/lib/python2.7/site-packages/ScriptTest-1.2-py2.7.egg/scripttest/__init__.py", line 237, in run
    env=clean_environ(self.environ))
  File "/Library/Frameworks/Python.framework/Versions/7.3/lib/python2.7/subprocess.py", line 679, in __init__
    errread, errwrite)
  File "/Library/Frameworks/Python.framework/Versions/7.3/lib/python2.7/subprocess.py", line 1249, in _execute_child
    raise child_exception

test s_tilt.py: [Errno 2] No such file or directory.  
Traceback below: 
  File "/Users/nebula/Python/PmagPy/Command_line_Tests/error_logging.py", line 27, in go_through
    v()
  File "Rename_me.py", line 703, in complete_s_tilt_test
    s_tilt.file_in_file_out_sequence()
  File "Rename_me.py", line 183, in file_in_file_out_sequence
    self.test_help()
  File "Rename_me.py", line 161, in test_help
    obj = env.run(self.name, '-h')
  File "/Library/Frameworks/Python.framework/Versions/7.3/lib/python2.7/site-packages/ScriptTest-1.2-py2.7.egg/scripttest/__init__.py", line 237, in run
    env=clean_environ(self.environ))
  File "/Library/Frameworks/Python.framework/Versions/7.3/lib/python2.7/subprocess.py", line 679, in __init__
    errread, errwrite)
  File "/Library/Frameworks/Python.framework/Versions/7.3/lib/python2.7/subprocess.py", line 1249, in _execute_child
    raise child_exception

test agm_magic.py: [Errno 2] No such file or directory.  
Traceback below: 
  File "/Users/nebula/Python/PmagPy/Command_line_Tests/error_logging.py", line 27, in go_through
    v()
  File "Rename_me.py", line 1227, in complete_agm_magic_test
    agm.file_in_file_out_sequence()
  File "Rename_me.py", line 183, in file_in_file_out_sequence
    self.test_help()
  File "Rename_me.py", line 161, in test_help
    obj = env.run(self.name, '-h')
  File "/Library/Frameworks/Python.framework/Versions/7.3/lib/python2.7/site-packages/ScriptTest-1.2-py2.7.egg/scripttest/__init__.py", line 237, in run
    env=clean_environ(self.environ))
  File "/Library/Frameworks/Python.framework/Versions/7.3/lib/python2.7/subprocess.py", line 679, in __init__
    errread, errwrite)
  File "/Library/Frameworks/Python.framework/Versions/7.3/lib/python2.7/subprocess.py", line 1249, in _execute_child
    raise child_exception

test common_mean.py: [Errno 2] No such file or directory.  
Traceback below: 
  File "/Users/nebula/Python/PmagPy/Command_line_Tests/error_logging.py", line 27, in go_through
    v()
  File "Rename_me.py", line 800, in complete_common_mean_test
    common_mean.plot_program_sequence(stdout=False)
  File "Rename_me.py", line 192, in plot_program_sequence
    self.test_help()
  File "Rename_me.py", line 161, in test_help
    obj = env.run(self.name, '-h')
  File "/Library/Frameworks/Python.framework/Versions/7.3/lib/python2.7/site-packages/ScriptTest-1.2-py2.7.egg/scripttest/__init__.py", line 237, in run
    env=clean_environ(self.environ))
  File "/Library/Frameworks/Python.framework/Versions/7.3/lib/python2.7/subprocess.py", line 679, in __init__
    errread, errwrite)
  File "/Library/Frameworks/Python.framework/Versions/7.3/lib/python2.7/subprocess.py", line 1249, in _execute_child
    raise child_exception

test gokent.py: [Errno 2] No such file or directory.  
Traceback below: 
  File "/Users/nebula/Python/PmagPy/Command_line_Tests/error_logging.py", line 27, in go_through
    v()
  File "Rename_me.py", line 637, in complete_gokent_test
    gokent.file_in_file_out_sequence()
  File "Rename_me.py", line 183, in file_in_file_out_sequence
    self.test_help()
  File "Rename_me.py", line 161, in test_help
    obj = env.run(self.name, '-h')
  File "/Library/Frameworks/Python.framework/Versions/7.3/lib/python2.7/site-packages/ScriptTest-1.2-py2.7.egg/scripttest/__init__.py", line 237, in run
    env=clean_environ(self.environ))
  File "/Library/Frameworks/Python.framework/Versions/7.3/lib/python2.7/subprocess.py", line 679, in __init__
    errread, errwrite)
  File "/Library/Frameworks/Python.framework/Versions/7.3/lib/python2.7/subprocess.py", line 1249, in _execute_child
    raise child_exception

test eigs_s.py: [Errno 2] No such file or directory.  
Traceback below: 
  File "/Users/nebula/Python/PmagPy/Command_line_Tests/error_logging.py", line 27, in go_through
    v()
  File "Rename_me.py", line 617, in complete_eigs_s_test
    eigs_s.file_in_file_out_sequence()
  File "Rename_me.py", line 183, in file_in_file_out_sequence
    self.test_help()
  File "Rename_me.py", line 161, in test_help
    obj = env.run(self.name, '-h')
  File "/Library/Frameworks/Python.framework/Versions/7.3/lib/python2.7/site-packages/ScriptTest-1.2-py2.7.egg/scripttest/__init__.py", line 237, in run
    env=clean_environ(self.environ))
  File "/Library/Frameworks/Python.framework/Versions/7.3/lib/python2.7/subprocess.py", line 679, in __init__
    errread, errwrite)
  File "/Library/Frameworks/Python.framework/Versions/7.3/lib/python2.7/subprocess.py", line 1249, in _execute_child
    raise child_exception

test lnp_magic.py: [Errno 2] No such file or directory.  
Traceback below: 
  File "/Users/nebula/Python/PmagPy/Command_line_Tests/error_logging.py", line 27, in go_through
    v()
  File "Rename_me.py", line 927, in complete_lnp_magic_test
    lnp_magic.run_program()
  File "Rename_me.py", line 79, in run_program
    obj = env.run(self.name, '-WD', directory, '-f', self.infile, '-F', self.outfile, self.arg_0, self.arg_1, self.arg_2, self.arg_3, self.arg_4, self.arg_5, stdin=self.stdin)
  File "/Library/Frameworks/Python.framework/Versions/7.3/lib/python2.7/site-packages/ScriptTest-1.2-py2.7.egg/scripttest/__init__.py", line 237, in run
    env=clean_environ(self.environ))
  File "/Library/Frameworks/Python.framework/Versions/7.3/lib/python2.7/subprocess.py", line 679, in __init__
    errread, errwrite)
  File "/Library/Frameworks/Python.framework/Versions/7.3/lib/python2.7/subprocess.py", line 1249, in _execute_child
    raise child_exception

test vgp_di.py: [Errno 2] No such file or directory.  
Traceback below: 
  File "/Users/nebula/Python/PmagPy/Command_line_Tests/error_logging.py", line 27, in go_through
    v()
  File "Rename_me.py", line 549, in complete_vgp_di_test
    vgp_di.list_sequence()
  File "Rename_me.py", line 203, in list_sequence
    result = self.run_program(output_type = "stdout")
  File "Rename_me.py", line 83, in run_program
    obj = env.run(self.name, '-f', self.infile, '-F', self.outfile, self.arg_0, self.arg_1, self.arg_2, self.arg_3, self.arg_4, self.arg_5, stdin=self.stdin)
  File "/Library/Frameworks/Python.framework/Versions/7.3/lib/python2.7/site-packages/ScriptTest-1.2-py2.7.egg/scripttest/__init__.py", line 237, in run
    env=clean_environ(self.environ))
  File "/Library/Frameworks/Python.framework/Versions/7.3/lib/python2.7/subprocess.py", line 679, in __init__
    errread, errwrite)
  File "/Library/Frameworks/Python.framework/Versions/7.3/lib/python2.7/subprocess.py", line 1249, in _execute_child
    raise child_exception

test convert_samples.py: [Errno 2] No such file or directory.  
Traceback below: 
  File "/Users/nebula/Python/PmagPy/Command_line_Tests/error_logging.py", line 27, in go_through
    v()
  File "Rename_me.py", line 582, in complete_convert_samples_test
    obj = env.run('convert_samples.py', '-f', 'convert_samples_example.dat', '-WD', directory, '-OD', directory)
  File "/Library/Frameworks/Python.framework/Versions/7.3/lib/python2.7/site-packages/ScriptTest-1.2-py2.7.egg/scripttest/__init__.py", line 237, in run
    env=clean_environ(self.environ))
  File "/Library/Frameworks/Python.framework/Versions/7.3/lib/python2.7/subprocess.py", line 679, in __init__
    errread, errwrite)
  File "/Library/Frameworks/Python.framework/Versions/7.3/lib/python2.7/subprocess.py", line 1249, in _execute_child
    raise child_exception

test customize_criteria.py: [Errno 2] No such file or directory.  
Traceback below: 
  File "/Users/nebula/Python/PmagPy/Command_line_Tests/error_logging.py", line 27, in go_through
    v()
  File "Rename_me.py", line 399, in complete_customize_criteria_test
    customize_criteria.file_in_file_out_sequence(interactive=True)
  File "Rename_me.py", line 183, in file_in_file_out_sequence
    self.test_help()
  File "Rename_me.py", line 161, in test_help
    obj = env.run(self.name, '-h')
  File "/Library/Frameworks/Python.framework/Versions/7.3/lib/python2.7/site-packages/ScriptTest-1.2-py2.7.egg/scripttest/__init__.py", line 237, in run
    env=clean_environ(self.environ))
  File "/Library/Frameworks/Python.framework/Versions/7.3/lib/python2.7/subprocess.py", line 679, in __init__
    errread, errwrite)
  File "/Library/Frameworks/Python.framework/Versions/7.3/lib/python2.7/subprocess.py", line 1249, in _execute_child
    raise child_exception

test di_rot.py: [Errno 2] No such file or directory.  
Traceback below: 
  File "/Users/nebula/Python/PmagPy/Command_line_Tests/error_logging.py", line 27, in go_through
    v()
  File "Rename_me.py", line 607, in complete_di_rot_test
    di_rot.file_in_file_out_sequence()
  File "Rename_me.py", line 183, in file_in_file_out_sequence
    self.test_help()
  File "Rename_me.py", line 161, in test_help
    obj = env.run(self.name, '-h')
  File "/Library/Frameworks/Python.framework/Versions/7.3/lib/python2.7/site-packages/ScriptTest-1.2-py2.7.egg/scripttest/__init__.py", line 237, in run
    env=clean_environ(self.environ))
  File "/Library/Frameworks/Python.framework/Versions/7.3/lib/python2.7/subprocess.py", line 679, in __init__
    errread, errwrite)
  File "/Library/Frameworks/Python.framework/Versions/7.3/lib/python2.7/subprocess.py", line 1249, in _execute_child
    raise child_exception

test scalc_magic.py: [Errno 2] No such file or directory.  
Traceback below: 
  File "/Users/nebula/Python/PmagPy/Command_line_Tests/error_logging.py", line 27, in go_through
    v()
  File "Rename_me.py", line 525, in complete_scalc_magic_test
    scalc_magic.list_sequence()
  File "Rename_me.py", line 203, in list_sequence
    result = self.run_program(output_type = "stdout")
  File "Rename_me.py", line 83, in run_program
    obj = env.run(self.name, '-f', self.infile, '-F', self.outfile, self.arg_0, self.arg_1, self.arg_2, self.arg_3, self.arg_4, self.arg_5, stdin=self.stdin)
  File "/Library/Frameworks/Python.framework/Versions/7.3/lib/python2.7/site-packages/ScriptTest-1.2-py2.7.egg/scripttest/__init__.py", line 237, in run
    env=clean_environ(self.environ))
  File "/Library/Frameworks/Python.framework/Versions/7.3/lib/python2.7/subprocess.py", line 679, in __init__
    errread, errwrite)
  File "/Library/Frameworks/Python.framework/Versions/7.3/lib/python2.7/subprocess.py", line 1249, in _execute_child
    raise child_exception

test plot_cdf.py: [Errno 2] No such file or directory.  
Traceback below: 
  File "/Users/nebula/Python/PmagPy/Command_line_Tests/error_logging.py", line 27, in go_through
    v()
  File "Rename_me.py", line 965, in complete_plot_cdf_test
    plot_cdf.plot_program_sequence(stdout=False)
  File "Rename_me.py", line 192, in plot_program_sequence
    self.test_help()
  File "Rename_me.py", line 161, in test_help
    obj = env.run(self.name, '-h')
  File "/Library/Frameworks/Python.framework/Versions/7.3/lib/python2.7/site-packages/ScriptTest-1.2-py2.7.egg/scripttest/__init__.py", line 237, in run
    env=clean_environ(self.environ))
  File "/Library/Frameworks/Python.framework/Versions/7.3/lib/python2.7/subprocess.py", line 679, in __init__
    errread, errwrite)
  File "/Library/Frameworks/Python.framework/Versions/7.3/lib/python2.7/subprocess.py", line 1249, in _execute_child
    raise child_exception

test_site_edit_magic.py: [Errno 2] No such file or directory.  
Traceback below: 
  File "/Users/nebula/Python/PmagPy/Command_line_Tests/error_logging.py", line 27, in go_through
    v()
  File "Rename_me.py", line 1062, in complete_site_edit_magic_test
    site_edit.plot_program_sequence(stdout=True)
  File "Rename_me.py", line 192, in plot_program_sequence
    self.test_help()
  File "Rename_me.py", line 161, in test_help
    obj = env.run(self.name, '-h')
  File "/Library/Frameworks/Python.framework/Versions/7.3/lib/python2.7/site-packages/ScriptTest-1.2-py2.7.egg/scripttest/__init__.py", line 237, in run
    env=clean_environ(self.environ))
  File "/Library/Frameworks/Python.framework/Versions/7.3/lib/python2.7/subprocess.py", line 679, in __init__
    errread, errwrite)
  File "/Library/Frameworks/Python.framework/Versions/7.3/lib/python2.7/subprocess.py", line 1249, in _execute_child
    raise child_exception

test mk_redo.py: [Errno 2] No such file or directory.  
Traceback below: 
  File "/Users/nebula/Python/PmagPy/Command_line_Tests/error_logging.py", line 27, in go_through
    v()
  File "Rename_me.py", line 688, in complete_mk_redo_test
    mk_redo.file_in_file_out_sequence()
  File "Rename_me.py", line 183, in file_in_file_out_sequence
    self.test_help()
  File "Rename_me.py", line 161, in test_help
    obj = env.run(self.name, '-h')
  File "/Library/Frameworks/Python.framework/Versions/7.3/lib/python2.7/site-packages/ScriptTest-1.2-py2.7.egg/scripttest/__init__.py", line 237, in run
    env=clean_environ(self.environ))
  File "/Library/Frameworks/Python.framework/Versions/7.3/lib/python2.7/subprocess.py", line 679, in __init__
    errread, errwrite)
  File "/Library/Frameworks/Python.framework/Versions/7.3/lib/python2.7/subprocess.py", line 1249, in _execute_child
    raise child_exception

test eq_di.py: [Errno 2] No such file or directory.  
Traceback below: 
  File "/Users/nebula/Python/PmagPy/Command_line_Tests/error_logging.py", line 27, in go_through
    v()
  File "Rename_me.py", line 622, in complete_eq_di_test
    eq_di.file_in_file_out_sequence()
  File "Rename_me.py", line 183, in file_in_file_out_sequence
    self.test_help()
  File "Rename_me.py", line 161, in test_help
    obj = env.run(self.name, '-h')
  File "/Library/Frameworks/Python.framework/Versions/7.3/lib/python2.7/site-packages/ScriptTest-1.2-py2.7.egg/scripttest/__init__.py", line 237, in run
    env=clean_environ(self.environ))
  File "/Library/Frameworks/Python.framework/Versions/7.3/lib/python2.7/subprocess.py", line 679, in __init__
    errread, errwrite)
  File "/Library/Frameworks/Python.framework/Versions/7.3/lib/python2.7/subprocess.py", line 1249, in _execute_child
    raise child_exception

test vgpmap_magic.py: [Errno 2] No such file or directory.  
Traceback below: 
  File "/Users/nebula/Python/PmagPy/Command_line_Tests/error_logging.py", line 27, in go_through
    v()
  File "Rename_me.py", line 1090, in complete_vgpmap_magic_test
    vgpmap_magic.plot_program_sequence(stdout=False)
  File "Rename_me.py", line 192, in plot_program_sequence
    self.test_help()
  File "Rename_me.py", line 161, in test_help
    obj = env.run(self.name, '-h')
  File "/Library/Frameworks/Python.framework/Versions/7.3/lib/python2.7/site-packages/ScriptTest-1.2-py2.7.egg/scripttest/__init__.py", line 237, in run
    env=clean_environ(self.environ))
  File "/Library/Frameworks/Python.framework/Versions/7.3/lib/python2.7/subprocess.py", line 679, in __init__
    errread, errwrite)
  File "/Library/Frameworks/Python.framework/Versions/7.3/lib/python2.7/subprocess.py", line 1249, in _execute_child
    raise child_exception

test apwp.py: [Errno 2] No such file or directory.  
Traceback below: 
  File "/Users/nebula/Python/PmagPy/Command_line_Tests/error_logging.py", line 27, in go_through
    v()
  File "Rename_me.py", line 566, in complete_apwp_test
    apwp.file_in_file_out_sequence(interactive=True)
  File "Rename_me.py", line 183, in file_in_file_out_sequence
    self.test_help()
  File "Rename_me.py", line 161, in test_help
    obj = env.run(self.name, '-h')
  File "/Library/Frameworks/Python.framework/Versions/7.3/lib/python2.7/site-packages/ScriptTest-1.2-py2.7.egg/scripttest/__init__.py", line 237, in run
    env=clean_environ(self.environ))
  File "/Library/Frameworks/Python.framework/Versions/7.3/lib/python2.7/subprocess.py", line 679, in __init__
    errread, errwrite)
  File "/Library/Frameworks/Python.framework/Versions/7.3/lib/python2.7/subprocess.py", line 1249, in _execute_child
    raise child_exception

test di_tilt.py: [Errno 2] No such file or directory.  
Traceback below: 
  File "/Users/nebula/Python/PmagPy/Command_line_Tests/error_logging.py", line 27, in go_through
    v()
  File "Rename_me.py", line 597, in complete_di_tilt_test
    di_tilt.file_in_file_out_sequence(interactive=True)
  File "Rename_me.py", line 183, in file_in_file_out_sequence
    self.test_help()
  File "Rename_me.py", line 161, in test_help
    obj = env.run(self.name, '-h')
  File "/Library/Frameworks/Python.framework/Versions/7.3/lib/python2.7/site-packages/ScriptTest-1.2-py2.7.egg/scripttest/__init__.py", line 237, in run
    env=clean_environ(self.environ))
  File "/Library/Frameworks/Python.framework/Versions/7.3/lib/python2.7/subprocess.py", line 679, in __init__
    errread, errwrite)
  File "/Library/Frameworks/Python.framework/Versions/7.3/lib/python2.7/subprocess.py", line 1249, in _execute_child
    raise child_exception

test grab_magic_key.py: [Errno 2] No such file or directory.  
Traceback below: 
  File "/Users/nebula/Python/PmagPy/Command_line_Tests/error_logging.py", line 27, in go_through
    v()
  File "Rename_me.py", line 429, in complete_grab_magic_key_test
    grab_magic_key.list_sequence()
  File "Rename_me.py", line 203, in list_sequence
    result = self.run_program(output_type = "stdout")
  File "Rename_me.py", line 79, in run_program
    obj = env.run(self.name, '-WD', directory, '-f', self.infile, '-F', self.outfile, self.arg_0, self.arg_1, self.arg_2, self.arg_3, self.arg_4, self.arg_5, stdin=self.stdin)
  File "/Library/Frameworks/Python.framework/Versions/7.3/lib/python2.7/site-packages/ScriptTest-1.2-py2.7.egg/scripttest/__init__.py", line 237, in run
    env=clean_environ(self.environ))
  File "/Library/Frameworks/Python.framework/Versions/7.3/lib/python2.7/subprocess.py", line 679, in __init__
    errread, errwrite)
  File "/Library/Frameworks/Python.framework/Versions/7.3/lib/python2.7/subprocess.py", line 1249, in _execute_child
    raise child_exception

test revtest_magic.py: [Errno 2] No such file or directory.  
Traceback below: 
  File "/Users/nebula/Python/PmagPy/Command_line_Tests/error_logging.py", line 27, in go_through
    v()
  File "Rename_me.py", line 1039, in complete_revtest_magic_test
    revtest_magic.plot_program_sequence(stdout=False)
  File "Rename_me.py", line 192, in plot_program_sequence
    self.test_help()
  File "Rename_me.py", line 161, in test_help
    obj = env.run(self.name, '-h')
  File "/Library/Frameworks/Python.framework/Versions/7.3/lib/python2.7/site-packages/ScriptTest-1.2-py2.7.egg/scripttest/__init__.py", line 237, in run
    env=clean_environ(self.environ))
  File "/Library/Frameworks/Python.framework/Versions/7.3/lib/python2.7/subprocess.py", line 679, in __init__
    errread, errwrite)
  File "/Library/Frameworks/Python.framework/Versions/7.3/lib/python2.7/subprocess.py", line 1249, in _execute_child
    raise child_exception

test plot_magic_keys.py: [Errno 2] No such file or directory.  
Traceback below: 
  File "/Users/nebula/Python/PmagPy/Command_line_Tests/error_logging.py", line 27, in go_through
    v()
  File "Rename_me.py", line 1194, in complete_plot_magic_keys_test
    plot_magic_keys.run_program()
  File "Rename_me.py", line 79, in run_program
    obj = env.run(self.name, '-WD', directory, '-f', self.infile, '-F', self.outfile, self.arg_0, self.arg_1, self.arg_2, self.arg_3, self.arg_4, self.arg_5, stdin=self.stdin)
  File "/Library/Frameworks/Python.framework/Versions/7.3/lib/python2.7/site-packages/ScriptTest-1.2-py2.7.egg/scripttest/__init__.py", line 237, in run
    env=clean_environ(self.environ))
  File "/Library/Frameworks/Python.framework/Versions/7.3/lib/python2.7/subprocess.py", line 679, in __init__
    errread, errwrite)
  File "/Library/Frameworks/Python.framework/Versions/7.3/lib/python2.7/subprocess.py", line 1249, in _execute_child
    raise child_exception

test eqarea.py: [Errno 2] No such file or directory.  
Traceback below: 
  File "/Users/nebula/Python/PmagPy/Command_line_Tests/error_logging.py", line 27, in go_through
    v()
  File "Rename_me.py", line 844, in complete_eqarea_test
    eqarea.plot_program_sequence(stdout=False)
  File "Rename_me.py", line 192, in plot_program_sequence
    self.test_help()
  File "Rename_me.py", line 161, in test_help
    obj = env.run(self.name, '-h')
  File "/Library/Frameworks/Python.framework/Versions/7.3/lib/python2.7/site-packages/ScriptTest-1.2-py2.7.egg/scripttest/__init__.py", line 237, in run
    env=clean_environ(self.environ))
  File "/Library/Frameworks/Python.framework/Versions/7.3/lib/python2.7/subprocess.py", line 679, in __init__
    errread, errwrite)
  File "/Library/Frameworks/Python.framework/Versions/7.3/lib/python2.7/subprocess.py", line 1249, in _execute_child
    raise child_exception

test HUJI_magic.py: initializing variables were removed.  
Traceback below: 
  File "/Users/nebula/Python/PmagPy/Command_line_Tests/error_logging.py", line 27, in go_through
    v()
  File "Rename_me.py", line 1281, in complete_HUJI_magic_test
    raise NameError('initializing variables were removed')

test zeq_magic.py: [Errno 2] No such file or directory.  
Traceback below: 
  File "/Users/nebula/Python/PmagPy/Command_line_Tests/error_logging.py", line 27, in go_through
    v()
  File "Rename_me.py", line 1126, in complete_zeq_magic_test
    zeq_magic.plot_program_sequence(stdout=True)
  File "Rename_me.py", line 192, in plot_program_sequence
    self.test_help()
  File "Rename_me.py", line 161, in test_help
    obj = env.run(self.name, '-h')
  File "/Library/Frameworks/Python.framework/Versions/7.3/lib/python2.7/site-packages/ScriptTest-1.2-py2.7.egg/scripttest/__init__.py", line 237, in run
    env=clean_environ(self.environ))
  File "/Library/Frameworks/Python.framework/Versions/7.3/lib/python2.7/subprocess.py", line 679, in __init__
    errread, errwrite)
  File "/Library/Frameworks/Python.framework/Versions/7.3/lib/python2.7/subprocess.py", line 1249, in _execute_child
    raise child_exception

test core_depthplot.py: [Errno 2] No such file or directory.  
Traceback below: 
  File "/Users/nebula/Python/PmagPy/Command_line_Tests/error_logging.py", line 27, in go_through
    v()
  File "Rename_me.py", line 817, in complete_core_depthplot_test
    core_depthplot.plot_program_sequence(stdout=False)
  File "Rename_me.py", line 192, in plot_program_sequence
    self.test_help()
  File "Rename_me.py", line 161, in test_help
    obj = env.run(self.name, '-h')
  File "/Library/Frameworks/Python.framework/Versions/7.3/lib/python2.7/site-packages/ScriptTest-1.2-py2.7.egg/scripttest/__init__.py", line 237, in run
    env=clean_environ(self.environ))
  File "/Library/Frameworks/Python.framework/Versions/7.3/lib/python2.7/subprocess.py", line 679, in __init__
    errread, errwrite)
  File "/Library/Frameworks/Python.framework/Versions/7.3/lib/python2.7/subprocess.py", line 1249, in _execute_child
    raise child_exception

test dmag_magic.py: [Errno 2] No such file or directory.  
Traceback below: 
  File "/Users/nebula/Python/PmagPy/Command_line_Tests/error_logging.py", line 27, in go_through
    v()
  File "Rename_me.py", line 835, in complete_dmag_magic_test
    dmag_magic.plot_program_sequence(stdout=False)
  File "Rename_me.py", line 192, in plot_program_sequence
    self.test_help()
  File "Rename_me.py", line 161, in test_help
    obj = env.run(self.name, '-h')
  File "/Library/Frameworks/Python.framework/Versions/7.3/lib/python2.7/site-packages/ScriptTest-1.2-py2.7.egg/scripttest/__init__.py", line 237, in run
    env=clean_environ(self.environ))
  File "/Library/Frameworks/Python.framework/Versions/7.3/lib/python2.7/subprocess.py", line 679, in __init__
    errread, errwrite)
  File "/Library/Frameworks/Python.framework/Versions/7.3/lib/python2.7/subprocess.py", line 1249, in _execute_child
    raise child_exception

test s_magic.py: [Errno 2] No such file or directory.  
Traceback below: 
  File "/Users/nebula/Python/PmagPy/Command_line_Tests/error_logging.py", line 27, in go_through
    v()
  File "Rename_me.py", line 1215, in complete_s_magic_test
    s_magic.file_in_file_out_sequence()
  File "Rename_me.py", line 183, in file_in_file_out_sequence
    self.test_help()
  File "Rename_me.py", line 161, in test_help
    obj = env.run(self.name, '-h')
  File "/Library/Frameworks/Python.framework/Versions/7.3/lib/python2.7/site-packages/ScriptTest-1.2-py2.7.egg/scripttest/__init__.py", line 237, in run
    env=clean_environ(self.environ))
  File "/Library/Frameworks/Python.framework/Versions/7.3/lib/python2.7/subprocess.py", line 679, in __init__
    errread, errwrite)
  File "/Library/Frameworks/Python.framework/Versions/7.3/lib/python2.7/subprocess.py", line 1249, in _execute_child
    raise child_exception

test dipole_pinc.py: [Errno 2] No such file or directory.  
Traceback below: 
  File "/Users/nebula/Python/PmagPy/Command_line_Tests/error_logging.py", line 27, in go_through
    v()
  File "Rename_me.py", line 408, in complete_dipole_pinc_test
    dipole_pinc.list_sequence()
  File "Rename_me.py", line 203, in list_sequence
    result = self.run_program(output_type = "stdout")
  File "Rename_me.py", line 83, in run_program
    obj = env.run(self.name, '-f', self.infile, '-F', self.outfile, self.arg_0, self.arg_1, self.arg_2, self.arg_3, self.arg_4, self.arg_5, stdin=self.stdin)
  File "/Library/Frameworks/Python.framework/Versions/7.3/lib/python2.7/site-packages/ScriptTest-1.2-py2.7.egg/scripttest/__init__.py", line 237, in run
    env=clean_environ(self.environ))
  File "/Library/Frameworks/Python.framework/Versions/7.3/lib/python2.7/subprocess.py", line 679, in __init__
    errread, errwrite)
  File "/Library/Frameworks/Python.framework/Versions/7.3/lib/python2.7/subprocess.py", line 1249, in _execute_child
    raise child_exception

test histplot.py: [Errno 2] No such file or directory.  
Traceback below: 
  File "/Users/nebula/Python/PmagPy/Command_line_Tests/error_logging.py", line 27, in go_through
    v()
  File "Rename_me.py", line 905, in complete_histplot_test
    histplot.plot_program_sequence(stdout=False)
  File "Rename_me.py", line 192, in plot_program_sequence
    self.test_help()
  File "Rename_me.py", line 161, in test_help
    obj = env.run(self.name, '-h')
  File "/Library/Frameworks/Python.framework/Versions/7.3/lib/python2.7/site-packages/ScriptTest-1.2-py2.7.egg/scripttest/__init__.py", line 237, in run
    env=clean_environ(self.environ))
  File "/Library/Frameworks/Python.framework/Versions/7.3/lib/python2.7/subprocess.py", line 679, in __init__
    errread, errwrite)
  File "/Library/Frameworks/Python.framework/Versions/7.3/lib/python2.7/subprocess.py", line 1249, in _execute_child
    raise child_exception

test chartmaker.py: [Errno 2] No such file or directory.  
Traceback below: 
  File "/Users/nebula/Python/PmagPy/Command_line_Tests/error_logging.py", line 27, in go_through
    v()
  File "Rename_me.py", line 290, in complete_chartmaker_test
    chartmaker.plot_program_sequence(stdout=False)
  File "Rename_me.py", line 192, in plot_program_sequence
    self.test_help()
  File "Rename_me.py", line 161, in test_help
    obj = env.run(self.name, '-h')
  File "/Library/Frameworks/Python.framework/Versions/7.3/lib/python2.7/site-packages/ScriptTest-1.2-py2.7.egg/scripttest/__init__.py", line 237, in run
    env=clean_environ(self.environ))
  File "/Library/Frameworks/Python.framework/Versions/7.3/lib/python2.7/subprocess.py", line 679, in __init__
    errread, errwrite)
  File "/Library/Frameworks/Python.framework/Versions/7.3/lib/python2.7/subprocess.py", line 1249, in _execute_child
    raise child_exception

test eqarea_ell.py: [Errno 2] No such file or directory.  
Traceback below: 
  File "/Users/nebula/Python/PmagPy/Command_line_Tests/error_logging.py", line 27, in go_through
    v()
  File "Rename_me.py", line 862, in complete_eqarea_ell_test
    eqarea_ell.plot_program_sequence(stdout=True)
  File "Rename_me.py", line 192, in plot_program_sequence
    self.test_help()
  File "Rename_me.py", line 161, in test_help
    obj = env.run(self.name, '-h')
  File "/Library/Frameworks/Python.framework/Versions/7.3/lib/python2.7/site-packages/ScriptTest-1.2-py2.7.egg/scripttest/__init__.py", line 237, in run
    env=clean_environ(self.environ))
  File "/Library/Frameworks/Python.framework/Versions/7.3/lib/python2.7/subprocess.py", line 679, in __init__
    errread, errwrite)
  File "/Library/Frameworks/Python.framework/Versions/7.3/lib/python2.7/subprocess.py", line 1249, in _execute_child
    raise child_exception

test gofish.py: [Errno 2] No such file or directory.  
Traceback below: 
  File "/Users/nebula/Python/PmagPy/Command_line_Tests/error_logging.py", line 27, in go_through
    v()
  File "Rename_me.py", line 632, in complete_gofish_test
    gofish.file_in_file_out_sequence()
  File "Rename_me.py", line 183, in file_in_file_out_sequence
    self.test_help()
  File "Rename_me.py", line 161, in test_help
    obj = env.run(self.name, '-h')
  File "/Library/Frameworks/Python.framework/Versions/7.3/lib/python2.7/site-packages/ScriptTest-1.2-py2.7.egg/scripttest/__init__.py", line 237, in run
    env=clean_environ(self.environ))
  File "/Library/Frameworks/Python.framework/Versions/7.3/lib/python2.7/subprocess.py", line 679, in __init__
    errread, errwrite)
  File "/Library/Frameworks/Python.framework/Versions/7.3/lib/python2.7/subprocess.py", line 1249, in _execute_child
    raise child_exception

test LDEO_magic.py: [Errno 2] No such file or directory.  
Traceback below: 
  File "/Users/nebula/Python/PmagPy/Command_line_Tests/error_logging.py", line 27, in go_through
    v()
  File "Rename_me.py", line 1243, in complete_LDEO_magic_test
    ldeo_magic.file_in_file_out_sequence()
  File "Rename_me.py", line 183, in file_in_file_out_sequence
    self.test_help()
  File "Rename_me.py", line 161, in test_help
    obj = env.run(self.name, '-h')
  File "/Library/Frameworks/Python.framework/Versions/7.3/lib/python2.7/site-packages/ScriptTest-1.2-py2.7.egg/scripttest/__init__.py", line 237, in run
    env=clean_environ(self.environ))
  File "/Library/Frameworks/Python.framework/Versions/7.3/lib/python2.7/subprocess.py", line 679, in __init__
    errread, errwrite)
  File "/Library/Frameworks/Python.framework/Versions/7.3/lib/python2.7/subprocess.py", line 1249, in _execute_child
    raise child_exception

test gobing.py: [Errno 2] No such file or directory.  
Traceback below: 
  File "/Users/nebula/Python/PmagPy/Command_line_Tests/error_logging.py", line 27, in go_through
    v()
  File "Rename_me.py", line 627, in complete_gobing_test
    gobing.file_in_file_out_sequence()
  File "Rename_me.py", line 183, in file_in_file_out_sequence
    self.test_help()
  File "Rename_me.py", line 161, in test_help
    obj = env.run(self.name, '-h')
  File "/Library/Frameworks/Python.framework/Versions/7.3/lib/python2.7/site-packages/ScriptTest-1.2-py2.7.egg/scripttest/__init__.py", line 237, in run
    env=clean_environ(self.environ))
  File "/Library/Frameworks/Python.framework/Versions/7.3/lib/python2.7/subprocess.py", line 679, in __init__
    errread, errwrite)
  File "/Library/Frameworks/Python.framework/Versions/7.3/lib/python2.7/subprocess.py", line 1249, in _execute_child
    raise child_exception

test strip_magic.py: [Errno 2] No such file or directory.  
Traceback below: 
  File "/Users/nebula/Python/PmagPy/Command_line_Tests/error_logging.py", line 27, in go_through
    v()
  File "Rename_me.py", line 1071, in complete_strip_magic_test
    strip_magic.plot_program_sequence(stdout=False)
  File "Rename_me.py", line 192, in plot_program_sequence
    self.test_help()
  File "Rename_me.py", line 161, in test_help
    obj = env.run(self.name, '-h')
  File "/Library/Frameworks/Python.framework/Versions/7.3/lib/python2.7/site-packages/ScriptTest-1.2-py2.7.egg/scripttest/__init__.py", line 237, in run
    env=clean_environ(self.environ))
  File "/Library/Frameworks/Python.framework/Versions/7.3/lib/python2.7/subprocess.py", line 679, in __init__
    errread, errwrite)
  File "/Library/Frameworks/Python.framework/Versions/7.3/lib/python2.7/subprocess.py", line 1249, in _execute_child
    raise child_exception

test angle.py: [Errno 2] No such file or directory.  
Traceback below: 
  File "/Users/nebula/Python/PmagPy/Command_line_Tests/error_logging.py", line 27, in go_through
    v()
  File "Rename_me.py", line 257, in complete_angle_test
    angle.file_in_file_out_sequence(interactive=True)
  File "Rename_me.py", line 183, in file_in_file_out_sequence
    self.test_help()
  File "Rename_me.py", line 161, in test_help
    obj = env.run(self.name, '-h')
  File "/Library/Frameworks/Python.framework/Versions/7.3/lib/python2.7/site-packages/ScriptTest-1.2-py2.7.egg/scripttest/__init__.py", line 237, in run
    env=clean_environ(self.environ))
  File "/Library/Frameworks/Python.framework/Versions/7.3/lib/python2.7/subprocess.py", line 679, in __init__
    errread, errwrite)
  File "/Library/Frameworks/Python.framework/Versions/7.3/lib/python2.7/subprocess.py", line 1249, in _execute_child
    raise child_exception

test thellier_magic.py: [Errno 2] No such file or directory.  
Traceback below: 
  File "/Users/nebula/Python/PmagPy/Command_line_Tests/error_logging.py", line 27, in go_through
    v()
  File "Rename_me.py", line 1081, in complete_thellier_magic_test
    thellier_magic.list_sequence()
  File "Rename_me.py", line 203, in list_sequence
    result = self.run_program(output_type = "stdout")
  File "Rename_me.py", line 83, in run_program
    obj = env.run(self.name, '-f', self.infile, '-F', self.outfile, self.arg_0, self.arg_1, self.arg_2, self.arg_3, self.arg_4, self.arg_5, stdin=self.stdin)
  File "/Library/Frameworks/Python.framework/Versions/7.3/lib/python2.7/site-packages/ScriptTest-1.2-py2.7.egg/scripttest/__init__.py", line 237, in run
    env=clean_environ(self.environ))
  File "/Library/Frameworks/Python.framework/Versions/7.3/lib/python2.7/subprocess.py", line 679, in __init__
    errread, errwrite)
  File "/Library/Frameworks/Python.framework/Versions/7.3/lib/python2.7/subprocess.py", line 1249, in _execute_child
    raise child_exception

test foldtest_magic.py: [Errno 2] No such file or directory.  
Traceback below: 
  File "/Users/nebula/Python/PmagPy/Command_line_Tests/error_logging.py", line 27, in go_through
    v()
  File "Rename_me.py", line 885, in complete_foldtest_magic_test
    foldtest_magic.plot_program_sequence(stdout=False)
  File "Rename_me.py", line 192, in plot_program_sequence
    self.test_help()
  File "Rename_me.py", line 161, in test_help
    obj = env.run(self.name, '-h')
  File "/Library/Frameworks/Python.framework/Versions/7.3/lib/python2.7/site-packages/ScriptTest-1.2-py2.7.egg/scripttest/__init__.py", line 237, in run
    env=clean_environ(self.environ))
  File "/Library/Frameworks/Python.framework/Versions/7.3/lib/python2.7/subprocess.py", line 679, in __init__
    errread, errwrite)
  File "/Library/Frameworks/Python.framework/Versions/7.3/lib/python2.7/subprocess.py", line 1249, in _execute_child
    raise child_exception

test dipole_plat.py: [Errno 2] No such file or directory.  
Traceback below: 
  File "/Users/nebula/Python/PmagPy/Command_line_Tests/error_logging.py", line 27, in go_through
    v()
  File "Rename_me.py", line 417, in complete_dipole_plat_test
    dipole_plat.list_sequence()
  File "Rename_me.py", line 203, in list_sequence
    result = self.run_program(output_type = "stdout")
  File "Rename_me.py", line 83, in run_program
    obj = env.run(self.name, '-f', self.infile, '-F', self.outfile, self.arg_0, self.arg_1, self.arg_2, self.arg_3, self.arg_4, self.arg_5, stdin=self.stdin)
  File "/Library/Frameworks/Python.framework/Versions/7.3/lib/python2.7/site-packages/ScriptTest-1.2-py2.7.egg/scripttest/__init__.py", line 237, in run
    env=clean_environ(self.environ))
  File "/Library/Frameworks/Python.framework/Versions/7.3/lib/python2.7/subprocess.py", line 679, in __init__
    errread, errwrite)
  File "/Library/Frameworks/Python.framework/Versions/7.3/lib/python2.7/subprocess.py", line 1249, in _execute_child
    raise child_exception

test di_geo.py: [Errno 2] No such file or directory.  
Traceback below: 
  File "/Users/nebula/Python/PmagPy/Command_line_Tests/error_logging.py", line 27, in go_through
    v()
  File "Rename_me.py", line 592, in complete_di_geo_test
    di_geo.file_in_file_out_sequence(interactive=True)
  File "Rename_me.py", line 183, in file_in_file_out_sequence
    self.test_help()
  File "Rename_me.py", line 161, in test_help
    obj = env.run(self.name, '-h')
  File "/Library/Frameworks/Python.framework/Versions/7.3/lib/python2.7/site-packages/ScriptTest-1.2-py2.7.egg/scripttest/__init__.py", line 237, in run
    env=clean_environ(self.environ))
  File "/Library/Frameworks/Python.framework/Versions/7.3/lib/python2.7/subprocess.py", line 679, in __init__
    errread, errwrite)
  File "/Library/Frameworks/Python.framework/Versions/7.3/lib/python2.7/subprocess.py", line 1249, in _execute_child
    raise child_exception

test ani_depthplot.py: [Errno 2] No such file or directory.  
Traceback below: 
  File "/Users/nebula/Python/PmagPy/Command_line_Tests/error_logging.py", line 27, in go_through
    v()
  File "Rename_me.py", line 743, in complete_ani_depthplot_test
    ani_depthplot.plot_program_sequence(stdout=False)
  File "Rename_me.py", line 192, in plot_program_sequence
    self.test_help()
  File "Rename_me.py", line 161, in test_help
    obj = env.run(self.name, '-h')
  File "/Library/Frameworks/Python.framework/Versions/7.3/lib/python2.7/site-packages/ScriptTest-1.2-py2.7.egg/scripttest/__init__.py", line 237, in run
    env=clean_environ(self.environ))
  File "/Library/Frameworks/Python.framework/Versions/7.3/lib/python2.7/subprocess.py", line 679, in __init__
    errread, errwrite)
  File "/Library/Frameworks/Python.framework/Versions/7.3/lib/python2.7/subprocess.py", line 1249, in _execute_child
    raise child_exception

test sundec.py: [Errno 2] No such file or directory.  
Traceback below: 
  File "/Users/nebula/Python/PmagPy/Command_line_Tests/error_logging.py", line 27, in go_through
    v()
  File "Rename_me.py", line 470, in complete_sundec_test
    sundec.run_program()
  File "Rename_me.py", line 83, in run_program
    obj = env.run(self.name, '-f', self.infile, '-F', self.outfile, self.arg_0, self.arg_1, self.arg_2, self.arg_3, self.arg_4, self.arg_5, stdin=self.stdin)
  File "/Library/Frameworks/Python.framework/Versions/7.3/lib/python2.7/site-packages/ScriptTest-1.2-py2.7.egg/scripttest/__init__.py", line 237, in run
    env=clean_environ(self.environ))
  File "/Library/Frameworks/Python.framework/Versions/7.3/lib/python2.7/subprocess.py", line 679, in __init__
    errread, errwrite)
  File "/Library/Frameworks/Python.framework/Versions/7.3/lib/python2.7/subprocess.py", line 1249, in _execute_child
    raise child_exception

test lowrie.py: [Errno 2] No such file or directory.  
Traceback below: 
  File "/Users/nebula/Python/PmagPy/Command_line_Tests/error_logging.py", line 27, in go_through
    v()
  File "Rename_me.py", line 943, in complete_lowrie_test
    lowrie.plot_program_sequence(stdout=True)
  File "Rename_me.py", line 192, in plot_program_sequence
    self.test_help()
  File "Rename_me.py", line 161, in test_help
    obj = env.run(self.name, '-h')
  File "/Library/Frameworks/Python.framework/Versions/7.3/lib/python2.7/site-packages/ScriptTest-1.2-py2.7.egg/scripttest/__init__.py", line 237, in run
    env=clean_environ(self.environ))
  File "/Library/Frameworks/Python.framework/Versions/7.3/lib/python2.7/subprocess.py", line 679, in __init__
    errread, errwrite)
  File "/Library/Frameworks/Python.framework/Versions/7.3/lib/python2.7/subprocess.py", line 1249, in _execute_child
    raise child_exception

test download_magic.py: [Errno 2] No such file or directory.  
Traceback below: 
  File "/Users/nebula/Python/PmagPy/Command_line_Tests/error_logging.py", line 27, in go_through
    v()
  File "Rename_me.py", line 358, in complete_download_magic_test
    output = str(download_magic.run_program()).split()
  File "Rename_me.py", line 79, in run_program
    obj = env.run(self.name, '-WD', directory, '-f', self.infile, '-F', self.outfile, self.arg_0, self.arg_1, self.arg_2, self.arg_3, self.arg_4, self.arg_5, stdin=self.stdin)
  File "/Library/Frameworks/Python.framework/Versions/7.3/lib/python2.7/site-packages/ScriptTest-1.2-py2.7.egg/scripttest/__init__.py", line 237, in run
    env=clean_environ(self.environ))
  File "/Library/Frameworks/Python.framework/Versions/7.3/lib/python2.7/subprocess.py", line 679, in __init__
    errread, errwrite)
  File "/Library/Frameworks/Python.framework/Versions/7.3/lib/python2.7/subprocess.py", line 1249, in _execute_child
    raise child_exception

test k15.py: [Errno 2] No such file or directory.  
Traceback below: 
  File "/Users/nebula/Python/PmagPy/Command_line_Tests/error_logging.py", line 27, in go_through
    v()
  File "Rename_me.py", line 672, in complete_k15_s_test
    k15_s.file_in_file_out_sequence()
  File "Rename_me.py", line 183, in file_in_file_out_sequence
    self.test_help()
  File "Rename_me.py", line 161, in test_help
    obj = env.run(self.name, '-h')
  File "/Library/Frameworks/Python.framework/Versions/7.3/lib/python2.7/site-packages/ScriptTest-1.2-py2.7.egg/scripttest/__init__.py", line 237, in run
    env=clean_environ(self.environ))
  File "/Library/Frameworks/Python.framework/Versions/7.3/lib/python2.7/subprocess.py", line 679, in __init__
    errread, errwrite)
  File "/Library/Frameworks/Python.framework/Versions/7.3/lib/python2.7/subprocess.py", line 1249, in _execute_child
    raise child_exception

test convert2unix.py: [Errno 2] No such file or directory.  
Traceback below: 
  File "/Users/nebula/Python/PmagPy/Command_line_Tests/error_logging.py", line 27, in go_through
    v()
  File "Rename_me.py", line 1165, in complete_convert2unix_test
    obj = env.run("convert2unix.py", "-h")
  File "/Library/Frameworks/Python.framework/Versions/7.3/lib/python2.7/site-packages/ScriptTest-1.2-py2.7.egg/scripttest/__init__.py", line 237, in run
    env=clean_environ(self.environ))
  File "/Library/Frameworks/Python.framework/Versions/7.3/lib/python2.7/subprocess.py", line 679, in __init__
    errread, errwrite)
  File "/Library/Frameworks/Python.framework/Versions/7.3/lib/python2.7/subprocess.py", line 1249, in _execute_child
    raise child_exception

test di_vgp.py: [Errno 2] No such file or directory.  
Traceback below: 
  File "/Users/nebula/Python/PmagPy/Command_line_Tests/error_logging.py", line 27, in go_through
    v()
  File "Rename_me.py", line 612, in complete_di_vgp_test
    di_vgp.file_in_file_out_sequence(interactive=True)
  File "Rename_me.py", line 183, in file_in_file_out_sequence
    self.test_help()
  File "Rename_me.py", line 161, in test_help
    obj = env.run(self.name, '-h')
  File "/Library/Frameworks/Python.framework/Versions/7.3/lib/python2.7/site-packages/ScriptTest-1.2-py2.7.egg/scripttest/__init__.py", line 237, in run
    env=clean_environ(self.environ))
  File "/Library/Frameworks/Python.framework/Versions/7.3/lib/python2.7/subprocess.py", line 679, in __init__
    errread, errwrite)
  File "/Library/Frameworks/Python.framework/Versions/7.3/lib/python2.7/subprocess.py", line 1249, in _execute_child
    raise child_exception

test cart_dir.py: [Errno 2] No such file or directory.  
Traceback below: 
  File "/Users/nebula/Python/PmagPy/Command_line_Tests/error_logging.py", line 27, in go_through
    v()
  File "Rename_me.py", line 576, in complete_cart_dir_test
    cart_dir.file_in_file_out_sequence(interactive=True)
  File "Rename_me.py", line 183, in file_in_file_out_sequence
    self.test_help()
  File "Rename_me.py", line 161, in test_help
    obj = env.run(self.name, '-h')
  File "/Library/Frameworks/Python.framework/Versions/7.3/lib/python2.7/site-packages/ScriptTest-1.2-py2.7.egg/scripttest/__init__.py", line 237, in run
    env=clean_environ(self.environ))
  File "/Library/Frameworks/Python.framework/Versions/7.3/lib/python2.7/subprocess.py", line 679, in __init__
    errread, errwrite)
  File "/Library/Frameworks/Python.framework/Versions/7.3/lib/python2.7/subprocess.py", line 1249, in _execute_child
    raise child_exception

test curie.py: [Errno 2] No such file or directory.  
Traceback below: 
  File "/Users/nebula/Python/PmagPy/Command_line_Tests/error_logging.py", line 27, in go_through
    v()
  File "Rename_me.py", line 1185, in complete_curie_test
    curie.plot_program_sequence()
  File "Rename_me.py", line 192, in plot_program_sequence
    self.test_help()
  File "Rename_me.py", line 161, in test_help
    obj = env.run(self.name, '-h')
  File "/Library/Frameworks/Python.framework/Versions/7.3/lib/python2.7/site-packages/ScriptTest-1.2-py2.7.egg/scripttest/__init__.py", line 237, in run
    env=clean_environ(self.environ))
  File "/Library/Frameworks/Python.framework/Versions/7.3/lib/python2.7/subprocess.py", line 679, in __init__
    errread, errwrite)
  File "/Library/Frameworks/Python.framework/Versions/7.3/lib/python2.7/subprocess.py", line 1249, in _execute_child
    raise child_exception

programs with errors: ['test quick_hyst.py', 'test magic_select.py', 'test irmaq_magic.py', 'test igrf.py', 'test zeq.py', 'test upload_magic.py', 'test_watsonsF.py', 'test b_vdm.py', 'test s_hext.py', 'test_plotXY.py', 'test pca_example.py', 'test plotdi_a.py', 'test sio_magic.py', 'test foldtest.py', 'test s_geo.py', 'test make_magic_plots.py', 'test dir_cart.py', 'test chi_magic.py', 'test qqplot.py', 'weird ani_depthplot_test', 'test measurements_normalize_test.py', 'test go_princ.py', 'test pt_rot.py', 'test tdt_magic.py', 'test dayplot_magic.py', 'test s_eigs.py', 'test lowrie_magic.py', 'test incfish.py', 'test_basemap_magic.py', 'test nrm_specimens_magic.py', 'test di_eq.py', 'test cont_rot.py', 'test azdip_magic.py', 'test stats.py', 'test scalc.py', 'test fishqq.py', 'test vector_mean.py', 'test revtest.py', 'test combine_magic_test.py', 'test vdm_b.py', 'test biplot_magic.py', 'test s_tilt.py', 'test agm_magic.py', 'test common_mean.py', 'test gokent.py', 'test eigs_s.py', 'test lnp_magic.py', 'test vgp_di.py', 'test convert_samples.py', 'test customize_criteria.py', 'test di_rot.py', 'test scalc_magic.py', 'test plot_cdf.py', 'test_site_edit_magic.py', 'test mk_redo.py', 'test eq_di.py', 'test vgpmap_magic.py', 'test apwp.py', 'test di_tilt.py', 'test grab_magic_key.py', 'test revtest_magic.py', 'test plot_magic_keys.py', 'test eqarea.py', 'test HUJI_magic.py', 'test zeq_magic.py', 'test core_depthplot.py', 'test dmag_magic.py', 'test s_magic.py', 'test dipole_pinc.py', 'test histplot.py', 'test chartmaker.py', 'test eqarea_ell.py', 'test gofish.py', 'test LDEO_magic.py', 'test gobing.py', 'test strip_magic.py', 'test angle.py', 'test thellier_magic.py', 'test foldtest_magic.py', 'test dipole_plat.py', 'test di_geo.py', 'test ani_depthplot.py', 'test sundec.py', 'test lowrie.py', 'test download_magic.py', 'test k15.py', 'test convert2unix.py', 'test di_vgp.py', 'test cart_dir.py', 'test curie.py']

random_errors_list:  
test tk03.py: [Errno 2] No such file or directory.  
Traceback below: 
  File "/Users/nebula/Python/PmagPy/Command_line_Tests/error_logging.py", line 27, in go_through
    v()
  File "Random.py", line 107, in complete_tk03_test
    obj = env.run('tk03.py', '-h')
  File "/Library/Frameworks/Python.framework/Versions/7.3/lib/python2.7/site-packages/ScriptTest-1.2-py2.7.egg/scripttest/__init__.py", line 237, in run
    env=clean_environ(self.environ))
  File "/Library/Frameworks/Python.framework/Versions/7.3/lib/python2.7/subprocess.py", line 679, in __init__
    errread, errwrite)
  File "/Library/Frameworks/Python.framework/Versions/7.3/lib/python2.7/subprocess.py", line 1249, in _execute_child
    raise child_exception

test fisher.py: [Errno 2] No such file or directory.  
Traceback below: 
  File "/Users/nebula/Python/PmagPy/Command_line_Tests/error_logging.py", line 27, in go_through
    v()
  File "Random.py", line 18, in complete_fisher_test
    obj1 = env.run('fisher.py', '-k', '30', '-n', '10')
  File "/Library/Frameworks/Python.framework/Versions/7.3/lib/python2.7/site-packages/ScriptTest-1.2-py2.7.egg/scripttest/__init__.py", line 237, in run
    env=clean_environ(self.environ))
  File "/Library/Frameworks/Python.framework/Versions/7.3/lib/python2.7/subprocess.py", line 679, in __init__
    errread, errwrite)
  File "/Library/Frameworks/Python.framework/Versions/7.3/lib/python2.7/subprocess.py", line 1249, in _execute_child
    raise child_exception

test gaussian.py: [Errno 2] No such file or directory.  
Traceback below: 
  File "/Users/nebula/Python/PmagPy/Command_line_Tests/error_logging.py", line 27, in go_through
    v()
  File "Random.py", line 171, in complete_gaussian_test
    obj = env.run('gaussian.py', '-h')
  File "/Library/Frameworks/Python.framework/Versions/7.3/lib/python2.7/site-packages/ScriptTest-1.2-py2.7.egg/scripttest/__init__.py", line 237, in run
    env=clean_environ(self.environ))
  File "/Library/Frameworks/Python.framework/Versions/7.3/lib/python2.7/subprocess.py", line 679, in __init__
    errread, errwrite)
  File "/Library/Frameworks/Python.framework/Versions/7.3/lib/python2.7/subprocess.py", line 1249, in _execute_child
    raise child_exception

test fishrot.py: [Errno 2] No such file or directory.  
Traceback below: 
  File "/Users/nebula/Python/PmagPy/Command_line_Tests/error_logging.py", line 27, in go_through
    v()
  File "Random.py", line 64, in complete_fishrot_test
    obj = env.run('fishrot.py', '-h')
  File "/Library/Frameworks/Python.framework/Versions/7.3/lib/python2.7/site-packages/ScriptTest-1.2-py2.7.egg/scripttest/__init__.py", line 237, in run
    env=clean_environ(self.environ))
  File "/Library/Frameworks/Python.framework/Versions/7.3/lib/python2.7/subprocess.py", line 679, in __init__
    errread, errwrite)
  File "/Library/Frameworks/Python.framework/Versions/7.3/lib/python2.7/subprocess.py", line 1249, in _execute_child
    raise child_exception

test uniform.py: [Errno 2] No such file or directory.  
Traceback below: 
  File "/Users/nebula/Python/PmagPy/Command_line_Tests/error_logging.py", line 27, in go_through
    v()
  File "Random.py", line 138, in complete_uniform_test
    obj = env.run('uniform.py', '-h')
  File "/Library/Frameworks/Python.framework/Versions/7.3/lib/python2.7/site-packages/ScriptTest-1.2-py2.7.egg/scripttest/__init__.py", line 237, in run
    env=clean_environ(self.environ))
  File "/Library/Frameworks/Python.framework/Versions/7.3/lib/python2.7/subprocess.py", line 679, in __init__
    errread, errwrite)
  File "/Library/Frameworks/Python.framework/Versions/7.3/lib/python2.7/subprocess.py", line 1249, in _execute_child
    raise child_exception

programs with errors: ['test tk03.py', 'test fisher.py', 'test gaussian.py', 'test fishrot.py', 'test uniform.py']

extra_output_errors_list:  
test hysteresis_magic.py: [Errno 2] No such file or directory.  
Traceback below: 
  File "/Users/nebula/Python/PmagPy/Command_line_Tests/error_logging.py", line 27, in go_through
    v()
  File "Extra_output.py", line 244, in complete_hysteresis_magic_test
    hysteresis_magic.run_program()
  File "Extra_output.py", line 63, in run_program
    obj = env.run(self.name, '-WD', directory, '-f', self.infile, self.tag1, self.outfile1, self.tag2, self.outfile2, self.arg1, self.arg2, self.arg3, self.arg4, stdin=self.stdin)
  File "/Library/Frameworks/Python.framework/Versions/7.3/lib/python2.7/site-packages/ScriptTest-1.2-py2.7.egg/scripttest/__init__.py", line 237, in run
    env=clean_environ(self.environ))
  File "/Library/Frameworks/Python.framework/Versions/7.3/lib/python2.7/subprocess.py", line 679, in __init__
    errread, errwrite)
  File "/Library/Frameworks/Python.framework/Versions/7.3/lib/python2.7/subprocess.py", line 1249, in _execute_child
    raise child_exception

test IODP_csv.py: [Errno 2] No such file or directory.  
Traceback below: 
  File "/Users/nebula/Python/PmagPy/Command_line_Tests/error_logging.py", line 27, in go_through
    v()
  File "Extra_output.py", line 435, in complete_IODP_csv_magic_test
    obj = env.run('IODP_csv_magic.py', '-h')
  File "/Library/Frameworks/Python.framework/Versions/7.3/lib/python2.7/site-packages/ScriptTest-1.2-py2.7.egg/scripttest/__init__.py", line 237, in run
    env=clean_environ(self.environ))
  File "/Library/Frameworks/Python.framework/Versions/7.3/lib/python2.7/subprocess.py", line 679, in __init__
    errread, errwrite)
  File "/Library/Frameworks/Python.framework/Versions/7.3/lib/python2.7/subprocess.py", line 1249, in _execute_child
    raise child_exception

None: [Errno 2] No such file or directory.  
Traceback below: 
  File "/Users/nebula/Python/PmagPy/Command_line_Tests/error_logging.py", line 27, in go_through
    v()
  File "Extra_output.py", line 460, in complete_SUFAR4_asc_magic_test
    sufar4.ex_out_sequence()
  File "Extra_output.py", line 139, in ex_out_sequence
    self.run_program()
  File "Extra_output.py", line 63, in run_program
    obj = env.run(self.name, '-WD', directory, '-f', self.infile, self.tag1, self.outfile1, self.tag2, self.outfile2, self.arg1, self.arg2, self.arg3, self.arg4, stdin=self.stdin)
  File "/Library/Frameworks/Python.framework/Versions/7.3/lib/python2.7/site-packages/ScriptTest-1.2-py2.7.egg/scripttest/__init__.py", line 237, in run
    env=clean_environ(self.environ))
  File "/Library/Frameworks/Python.framework/Versions/7.3/lib/python2.7/subprocess.py", line 679, in __init__
    errread, errwrite)
  File "/Library/Frameworks/Python.framework/Versions/7.3/lib/python2.7/subprocess.py", line 1249, in _execute_child
    raise child_exception

test pmag_results_extract.py: [Errno 2] No such file or directory.  
Traceback below: 
  File "/Users/nebula/Python/PmagPy/Command_line_Tests/error_logging.py", line 27, in go_through
    v()
  File "Extra_output.py", line 318, in complete_pmag_results_extract_test
    obj = env.run('pmag_results_extract.py', '-WD', directory, '-f', 'pmag_results_extract.dat')
  File "/Library/Frameworks/Python.framework/Versions/7.3/lib/python2.7/site-packages/ScriptTest-1.2-py2.7.egg/scripttest/__init__.py", line 237, in run
    env=clean_environ(self.environ))
  File "/Library/Frameworks/Python.framework/Versions/7.3/lib/python2.7/subprocess.py", line 679, in __init__
    errread, errwrite)
  File "/Library/Frameworks/Python.framework/Versions/7.3/lib/python2.7/subprocess.py", line 1249, in _execute_child
    raise child_exception

test parse_measurements_test(): [Errno 2] No such file or directory.  
Traceback below: 
  File "/Users/nebula/Python/PmagPy/Command_line_Tests/error_logging.py", line 27, in go_through
    v()
  File "Extra_output.py", line 353, in complete_parse_measurements_test
    parse_measurements.ex_out_sequence()
  File "Extra_output.py", line 139, in ex_out_sequence
    self.run_program()
  File "Extra_output.py", line 63, in run_program
    obj = env.run(self.name, '-WD', directory, '-f', self.infile, self.tag1, self.outfile1, self.tag2, self.outfile2, self.arg1, self.arg2, self.arg3, self.arg4, stdin=self.stdin)
  File "/Library/Frameworks/Python.framework/Versions/7.3/lib/python2.7/site-packages/ScriptTest-1.2-py2.7.egg/scripttest/__init__.py", line 237, in run
    env=clean_environ(self.environ))
  File "/Library/Frameworks/Python.framework/Versions/7.3/lib/python2.7/subprocess.py", line 679, in __init__
    errread, errwrite)
  File "/Library/Frameworks/Python.framework/Versions/7.3/lib/python2.7/subprocess.py", line 1249, in _execute_child
    raise child_exception

None: [Errno 2] No such file or directory.  
Traceback below: 
  File "/Users/nebula/Python/PmagPy/Command_line_Tests/error_logging.py", line 27, in go_through
    v()
  File "Extra_output.py", line 476, in complete_specimens_results_magic_test
    obj = env.run('specimens_results_magic.py', '-h', cwd = directory + '/specimens_results_magic')
  File "/Library/Frameworks/Python.framework/Versions/7.3/lib/python2.7/site-packages/ScriptTest-1.2-py2.7.egg/scripttest/__init__.py", line 237, in run
    env=clean_environ(self.environ))
  File "/Library/Frameworks/Python.framework/Versions/7.3/lib/python2.7/subprocess.py", line 679, in __init__
    errread, errwrite)
  File "/Library/Frameworks/Python.framework/Versions/7.3/lib/python2.7/subprocess.py", line 1249, in _execute_child
    raise child_exception

test thellier_magic_redo.py: [Errno 2] No such file or directory.  
Traceback below: 
  File "/Users/nebula/Python/PmagPy/Command_line_Tests/error_logging.py", line 27, in go_through
    v()
  File "Extra_output.py", line 371, in complete_thellier_magic_redo_test
    obj = env.run("thellier_magic_redo.py", "-WD", directory, "-f", infile, in_tag1, in1, in_tag2, in2, in_tag3, in3, "-F", outfile, out_tag1, out1, out_tag2, out2, arg1, arg2)
  File "/Library/Frameworks/Python.framework/Versions/7.3/lib/python2.7/site-packages/ScriptTest-1.2-py2.7.egg/scripttest/__init__.py", line 237, in run
    env=clean_environ(self.environ))
  File "/Library/Frameworks/Python.framework/Versions/7.3/lib/python2.7/subprocess.py", line 679, in __init__
    errread, errwrite)
  File "/Library/Frameworks/Python.framework/Versions/7.3/lib/python2.7/subprocess.py", line 1249, in _execute_child
    raise child_exception

test kly4s_magic.py: [Errno 2] No such file or directory.  
Traceback below: 
  File "/Users/nebula/Python/PmagPy/Command_line_Tests/error_logging.py", line 27, in go_through
    v()
  File "Extra_output.py", line 295, in complete_kly4s_magic_test
    obj = env.run('kly4s_magic.py', '-WD', directory, '-f', kly4s_infile, '-F', kly4s_F, '-Fa', kly4s_Fa)
  File "/Library/Frameworks/Python.framework/Versions/7.3/lib/python2.7/site-packages/ScriptTest-1.2-py2.7.egg/scripttest/__init__.py", line 237, in run
    env=clean_environ(self.environ))
  File "/Library/Frameworks/Python.framework/Versions/7.3/lib/python2.7/subprocess.py", line 679, in __init__
    errread, errwrite)
  File "/Library/Frameworks/Python.framework/Versions/7.3/lib/python2.7/subprocess.py", line 1249, in _execute_child
    raise child_exception

test CIT_magic.py: [Errno 2] No such file or directory.  
Traceback below: 
  File "/Users/nebula/Python/PmagPy/Command_line_Tests/error_logging.py", line 27, in go_through
    v()
  File "Extra_output.py", line 389, in complete_CIT_magic_test
    obj= env.run('CIT_magic.py', '-WD', directory, '-h')
  File "/Library/Frameworks/Python.framework/Versions/7.3/lib/python2.7/site-packages/ScriptTest-1.2-py2.7.egg/scripttest/__init__.py", line 237, in run
    env=clean_environ(self.environ))
  File "/Library/Frameworks/Python.framework/Versions/7.3/lib/python2.7/subprocess.py", line 679, in __init__
    errread, errwrite)
  File "/Library/Frameworks/Python.framework/Versions/7.3/lib/python2.7/subprocess.py", line 1249, in _execute_child
    raise child_exception

test k15_magic.py: [Errno 2] No such file or directory.  
Traceback below: 
  File "/Users/nebula/Python/PmagPy/Command_line_Tests/error_logging.py", line 27, in go_through
    v()
  File "Extra_output.py", line 265, in complete_k15_magic_test
    obj = env.run('k15_magic.py', '-WD', directory, '-f', k15_infile, '-Fsa', k15_Fsa, '-Fa', k15_Fa, '-F', k15_F)
  File "/Library/Frameworks/Python.framework/Versions/7.3/lib/python2.7/site-packages/ScriptTest-1.2-py2.7.egg/scripttest/__init__.py", line 237, in run
    env=clean_environ(self.environ))
  File "/Library/Frameworks/Python.framework/Versions/7.3/lib/python2.7/subprocess.py", line 679, in __init__
    errread, errwrite)
  File "/Library/Frameworks/Python.framework/Versions/7.3/lib/python2.7/subprocess.py", line 1249, in _execute_child
    raise child_exception

None: [Errno 2] No such file or directory.  
Traceback below: 
  File "/Users/nebula/Python/PmagPy/Command_line_Tests/error_logging.py", line 27, in go_through
    v()
  File "Extra_output.py", line 450, in complete_PMD_magic_test
    PMD_magic.ex_out_sequence()
  File "Extra_output.py", line 139, in ex_out_sequence
    self.run_program()
  File "Extra_output.py", line 63, in run_program
    obj = env.run(self.name, '-WD', directory, '-f', self.infile, self.tag1, self.outfile1, self.tag2, self.outfile2, self.arg1, self.arg2, self.arg3, self.arg4, stdin=self.stdin)
  File "/Library/Frameworks/Python.framework/Versions/7.3/lib/python2.7/site-packages/ScriptTest-1.2-py2.7.egg/scripttest/__init__.py", line 237, in run
    env=clean_environ(self.environ))
  File "/Library/Frameworks/Python.framework/Versions/7.3/lib/python2.7/subprocess.py", line 679, in __init__
    errread, errwrite)
  File "/Library/Frameworks/Python.framework/Versions/7.3/lib/python2.7/subprocess.py", line 1249, in _execute_child
    raise child_exception

testing aarm_magic.py: [Errno 2] No such file or directory.  
Traceback below: 
  File "/Users/nebula/Python/PmagPy/Command_line_Tests/error_logging.py", line 27, in go_through
    v()
  File "Extra_output.py", line 220, in complete_aarm_magic_test
    aarm_magic.ex_out_sequence()
  File "Extra_output.py", line 139, in ex_out_sequence
    self.run_program()
  File "Extra_output.py", line 63, in run_program
    obj = env.run(self.name, '-WD', directory, '-f', self.infile, self.tag1, self.outfile1, self.tag2, self.outfile2, self.arg1, self.arg2, self.arg3, self.arg4, stdin=self.stdin)
  File "/Library/Frameworks/Python.framework/Versions/7.3/lib/python2.7/site-packages/ScriptTest-1.2-py2.7.egg/scripttest/__init__.py", line 237, in run
    env=clean_environ(self.environ))
  File "/Library/Frameworks/Python.framework/Versions/7.3/lib/python2.7/subprocess.py", line 679, in __init__
    errread, errwrite)
  File "/Library/Frameworks/Python.framework/Versions/7.3/lib/python2.7/subprocess.py", line 1249, in _execute_child
    raise child_exception

test atrm_magic.py: [Errno 2] No such file or directory.  
Traceback below: 
  File "/Users/nebula/Python/PmagPy/Command_line_Tests/error_logging.py", line 27, in go_through
    v()
  File "Extra_output.py", line 231, in complete_atrm_magic_test
    atrm.ex_out_sequence()
  File "Extra_output.py", line 139, in ex_out_sequence
    self.run_program()
  File "Extra_output.py", line 63, in run_program
    obj = env.run(self.name, '-WD', directory, '-f', self.infile, self.tag1, self.outfile1, self.tag2, self.outfile2, self.arg1, self.arg2, self.arg3, self.arg4, stdin=self.stdin)
  File "/Library/Frameworks/Python.framework/Versions/7.3/lib/python2.7/site-packages/ScriptTest-1.2-py2.7.egg/scripttest/__init__.py", line 237, in run
    env=clean_environ(self.environ))
  File "/Library/Frameworks/Python.framework/Versions/7.3/lib/python2.7/subprocess.py", line 679, in __init__
    errread, errwrite)
  File "/Library/Frameworks/Python.framework/Versions/7.3/lib/python2.7/subprocess.py", line 1249, in _execute_child
    raise child_exception

test orientation_magic.py: [Errno 2] No such file or directory.  
Traceback below: 
  File "/Users/nebula/Python/PmagPy/Command_line_Tests/error_logging.py", line 27, in go_through
    v()
  File "Extra_output.py", line 342, in complete_orientation_magic_test
    orientation_magic.ex_out_sequence()
  File "Extra_output.py", line 139, in ex_out_sequence
    self.run_program()
  File "Extra_output.py", line 63, in run_program
    obj = env.run(self.name, '-WD', directory, '-f', self.infile, self.tag1, self.outfile1, self.tag2, self.outfile2, self.arg1, self.arg2, self.arg3, self.arg4, stdin=self.stdin)
  File "/Library/Frameworks/Python.framework/Versions/7.3/lib/python2.7/site-packages/ScriptTest-1.2-py2.7.egg/scripttest/__init__.py", line 237, in run
    env=clean_environ(self.environ))
  File "/Library/Frameworks/Python.framework/Versions/7.3/lib/python2.7/subprocess.py", line 679, in __init__
    errread, errwrite)
  File "/Library/Frameworks/Python.framework/Versions/7.3/lib/python2.7/subprocess.py", line 1249, in _execute_child
    raise child_exception

programs with errors: ['test hysteresis_magic.py', 'test IODP_csv.py', None, 'test pmag_results_extract.py', 'test parse_measurements_test()', None, 'test thellier_magic_redo.py', 'test kly4s_magic.py', 'test CIT_magic.py', 'test k15_magic.py', None, 'testing aarm_magic.py', 'test atrm_magic.py', 'test orientation_magic.py']

